Workbook

Sheet Terms of Use
A2: Terms of Use
A4: This Document is subject to the Adventis Terms of Use (“TOU”) appearing on its web site. The TOU include, but are not limited to, restrictions on use of Documents, a disclaimer of all warranties and conditions of merchantability, and limitations of liability.
A7: Product protected by copyright
A8: © 2013 Adventis CG Training LLC

Sheet Income Statement
A1: Adventis Air Company Financial Model | L1: This document subject to the Terms of Use
A2: Income Statement ($ in Millions) | L2: © 2013 Adventis CG Training LLC
E6: Fiscal Year Ended December 31,
E7: 2016A | F7: 2017A | G7: 2018A | H7: 2019E | I7: 2020E | J7: 2021E | K7: 2022E | L7: 2023E | N7: Instructions:
A8: Income Statement
A10: Revenue | E10: 1253.004 | F10: 1341.587 | G10: 1419.385 | H10: =+G10*(1+H11) -> 1525.8389 | I10: =+H10*(1+I11) -> 1617.3892 | J10: =+I10*(1+J11) -> 1698.2587 | K10: =+J10*(1+K11) -> 1757.6977 | L10: =+K10*(1+L11) -> 1810.4287 | N10: Previous Year's Revenue x (1 + Growth Rate)
A11: % Growth | F11: =+F10/E10-1 -> 0.070696502 | G11: =+G10/F10-1 -> 0.05798953 | H11: 0.075 | I11: 0.06 | J11: 0.05 | K11: 0.035 | L11: 0.03 | N11: Revenue / Previous Year's Revenue - 1
A13: Operating Expenses | E13: 1128.644 | F13: 1218.02 | G13: 1290.425 | H13: =+H10-H14 -> 1379.3583 | I13: =+I10-I14 -> 1463.7372 | J13: =+J10-J14 -> 1533.5276 | K13: =+K10-K14 -> 1585.4433 | L13: =+L10-L14 -> 1631.1962 | N13: Revenue - Operating Income
A14: Operating Income | E14: =+E10-E13 -> 124.36 | F14: =+F10-F13 -> 123.567 | G14: =+G10-G13 -> 128.96 | H14: =+H15*H10 -> 146.48053 | I14: =+I15*I10 -> 153.65197 | J14: =+J15*J10 -> 164.73109 | K14: =+K15*K10 -> 172.25438 | L14: =+L15*L10 -> 179.23244 | N14: % Operating Margin x Revenue
A15: % Operating Margin | E15: =+E14/E$10 -> 0.099249484 | F15: =+F14/F$10 -> 0.092105096 | G15: =+G14/G$10 -> 0.090856251 | H15: 0.096 | I15: 0.095 | J15: 0.097 | K15: 0.098 | L15: 0.099
A17: Interest Expense | E17: 19.674075 | F17: 22.466662 | G17: 24.004929 | H17: =Interest!H20 -> 26.38797 | I17: =Interest!I20 -> 25.68797 | J17: =Interest!J20 -> 23.315046 | K17: =Interest!K20 -> 20.550369 | L17: =Interest!L20 -> 18.845274 | N17: Step 10: Link into the Interest Expense Schedule
A18: Interest Income | E18: -9.030486 | F18: -8.906568 | G18: -6.986032 | H18: =-Interest!H32 -> -4.7742897 | I18: =-Interest!I32 -> -3.4751447 | J18: =-Interest!J32 -> -1.5035604 | K18: =-Interest!K32 -> -0.75 | L18: =-Interest!L32 -> -0.75 | N18: Step 10: Link into the Interest Income Schedule
A19: Other Expense (Income) | E19: -0.075 | F19: -1.226 | G19: -1.559 | H19: -4 | I19: -6 | J19: -7 | K19: -9 | L19: -11
A20: Total Other Expenses | E20: =SUM(E17:E19) -> 10.568589 | F20: =SUM(F17:F19) -> 12.334094 | G20: =SUM(G17:G19) -> 15.459897 | H20: =SUM(H17:H19) -> 17.61368 | I20: =SUM(I17:I19) -> 16.212825 | J20: =SUM(J17:J19) -> 14.811486 | K20: =SUM(K17:K19) -> 10.800369 | L20: =SUM(L17:L19) -> 7.0952741
A22: Earnings Before Taxes | E22: =+E14-E20 -> 113.79141 | F22: =+F14-F20 -> 111.23291 | G22: =+G14-G20 -> 113.5001 | H22: =+H14-H20 -> 128.86685 | I22: =+I14-I20 -> 137.43915 | J22: =+J14-J20 -> 149.9196 | K22: =+K14-K20 -> 161.45401 | L22: =+L14-L20 -> 172.13716 | N22: Operating Income - Total Other Expenses
A24: Corporate Taxes | E24: 41.480227 | F24: 40.377545 | G24: 29.850527 | H24: =+H22*H29 -> 34.149716 | I24: =+I22*I29 -> 36.421375 | J24: =+J22*J29 -> 39.728695 | K24: =+K22*K29 -> 42.785312 | L24: =+L22*L29 -> 45.616348 | N24: Earnings Before Taxes x Corporate Tax Rate
A25: Net Earnings | E25: =+E22-E24 -> 72.311185 | F25: =+F22-F24 -> 70.855361 | G25: =+G22-G24 -> 83.649576 | H25: =+H22-H24 -> 94.717136 | I25: =+I22-I24 -> 101.01777 | J25: =+J22-J24 -> 110.19091 | K25: =+K22-K24 -> 118.6687 | L25: =+L22-L24 -> 126.52081 | N25: Earnings Before Taxes - Corporate Taxes
A26: % Net Margin | E26: =+E25/E$10 -> 0.057710259 | F26: =+F25/F$10 -> 0.052814586 | G26: =+G25/G$10 -> 0.058933676 | H26: =+H25/H$10 -> 0.062075451 | I26: =+I25/I$10 -> 0.062457307 | J26: =+J25/J$10 -> 0.064884644 | K26: =+K25/K$10 -> 0.067513711 | L26: =+L25/L$10 -> 0.069884452 | N26: Net Earnings / Revenue
A28: Metrics & Drivers
A29: Corporate Tax Rate | E29: =+E24/E22 -> 0.36452862 | F29: =+F24/F22 -> 0.363 | G29: =+G24/G22 -> 0.263 | H29: 0.265 | I29: 0.265 | J29: 0.265 | K29: 0.265 | L29: 0.265 | N29: Corporate Taxes / Earnings before Taxes

Sheet Balance Sheet
A1: Adventis Air Company Financial Model | L1: This document subject to the Terms of Use
A2: Balance Sheet ($ in Millions) | L2: © 2013 Adventis CG Training LLC
E6: Fiscal Year Ended December 31,
E7: 2016A | F7: 2017A | G7: 2018A | H7: 2019E | I7: 2020E | J7: 2021E | K7: 2022E | L7: 2023E | N7: Instructions:
A8: Balance Sheet
A10: Cash and Cash Equivalents | E10: 274.32188 | F10: 277.49725 | G10: 161.84702 | H10: =+'Cash Flow Statement'!H27 -> 156.43896 | I10: =+'Cash Flow Statement'!I27 -> 75.237359 | J10: =+'Cash Flow Statement'!J27 -> 25 | K10: =+'Cash Flow Statement'!K27 -> 25 | L10: =+'Cash Flow Statement'!L27 -> 25 | N10: Step 6: Link into the Cash Flow Statement
A11: Accounts Receivable | E11: 21.815 | F11: 23.667 | G11: 24.563 | H11: =+'Working Capital'!H10 -> 27.172473 | I11: =+'Working Capital'!I10 -> 28.802822 | J11: =+'Working Capital'!J10 -> 30.160332 | K11: =+'Working Capital'!K10 -> 31.301466 | L11: =+'Working Capital'!L10 -> 32.24051 | N11: Step 7: Link into the Working Capital Schedule
A12: Other Current Assets | E12: 37.123 | F12: 38.615 | G12: 46.482 | H12: =+'Working Capital'!H11 -> 45.775166 | I12: =+'Working Capital'!I11 -> 48.521676 | J12: =+'Working Capital'!J11 -> 50.94776 | K12: =+'Working Capital'!K11 -> 52.730932 | L12: =+'Working Capital'!L11 -> 54.31286 | N12: Step 7: Link into the Working Capital Schedule
A13: Total Current Assets | E13: =SUM(E10:E12) -> 333.25988 | F13: =SUM(F10:F12) -> 339.77925 | G13: =SUM(G10:G12) -> 232.89202 | H13: =SUM(H10:H12) -> 229.3866 | I13: =SUM(I10:I12) -> 152.56186 | J13: =SUM(J10:J12) -> 106.10809 | K13: =SUM(K10:K12) -> 109.0324 | L13: =SUM(L10:L12) -> 111.55337
A15: Net Property, Plant & Equipment | E15: 857.765 | F15: 947.292 | G15: 1214.018 | H15: =+'PP&E'!H13 -> 1244.5348 | I15: =+'PP&E'!I13 -> 1349.6651 | J15: =+'PP&E'!J13 -> 1349.6651 | K15: =+'PP&E'!K13 -> 1358.4536 | L15: =+'PP&E'!L13 -> 1358.4536 | N15: Step 6: Link into the PP&E Schedule
A16: Other Long-Term Assets | E16: 66.622 | F16: 73.459 | G16: 49.516 | H16: 49.516 | I16: 49.516 | J16: 49.516 | K16: 49.516 | L16: 49.516
A17: Total Assets | E17: =SUM(E15:E16,E13) -> 1257.6469 | F17: =SUM(F15:F16,F13) -> 1360.5302 | G17: =SUM(G15:G16,G13) -> 1496.426 | H17: =SUM(H15:H16,H13) -> 1523.4374 | I17: =SUM(I15:I16,I13) -> 1551.7429 | J17: =SUM(J15:J16,J13) -> 1505.2892 | K17: =SUM(K15:K16,K13) -> 1517.002 | L17: =SUM(L15:L16,L13) -> 1519.5229
A19: Accounts Payable | E19: 6.901 | F19: 16.01 | G19: 20.108 | H19: =+'Working Capital'!H14 -> 19.072986 | I19: =+'Working Capital'!I14 -> 20.217365 | J19: =+'Working Capital'!J14 -> 21.228233 | K19: =+'Working Capital'!K14 -> 21.971222 | L19: =+'Working Capital'!L14 -> 22.630358 | N19: Step 7: Link into the Working Capital Schedule
A20: Accrued Liabilities | E20: 115.131 | F20: 96.661 | G20: 105.127 | H20: =+'Working Capital'!H15 -> 114.43792 | I20: =+'Working Capital'!I15 -> 121.30419 | J20: =+'Working Capital'!J15 -> 127.3694 | K20: =+'Working Capital'!K15 -> 131.82733 | L20: =+'Working Capital'!L15 -> 135.78215 | N20: Step 7: Link into the Working Capital Schedule
A21: Other Current Liabilities | E21: 197.136 | F21: 194.001 | G21: 210.184 | H21: =+'Working Capital'!H16 -> 228.87583 | I21: =+'Working Capital'!I16 -> 242.60838 | J21: =+'Working Capital'!J16 -> 254.7388 | K21: =+'Working Capital'!K16 -> 263.65466 | L21: =+'Working Capital'!L16 -> 271.5643 | N21: Step 7: Link into the Working Capital Schedule
A22: Total Current Liabilities | E22: =SUM(E19:E21) -> 319.168 | F22: =SUM(F19:F21) -> 306.672 | G22: =SUM(G19:G21) -> 335.419 | H22: =SUM(H19:H21) -> 362.38673 | I22: =SUM(I19:I21) -> 384.12994 | J22: =SUM(J19:J21) -> 403.33643 | K22: =SUM(K19:K21) -> 417.45321 | L22: =SUM(L19:L21) -> 429.97681
A24: Total Debt | E24: 588.18 | F24: 695.26 | G24: 763.942 | H24: =+Debt!H37 -> 743.942 | I24: =+Debt!I37 -> 723.942 | J24: =+Debt!J37 -> 622.41376 | K24: =+Debt!K37 -> 576.29686 | L24: =+Debt!L37 -> 515.40741 | N24: Step 9: Link into the Debt Schedule
A25: Other Long-Term Liabilities | E25: 49.255 | F25: 78.607 | G25: 122.14 | H25: 122.14 | I25: 122.14 | J25: 122.14 | K25: 122.14 | L25: 122.14
A26: Total Liabilities | E26: =SUM(E24:E25,E22) -> 956.603 | F26: =SUM(F24:F25,F22) -> 1080.539 | G26: =SUM(G24:G25,G22) -> 1221.501 | H26: =SUM(H24:H25,H22) -> 1228.4687 | I26: =SUM(I24:I25,I22) -> 1230.2119 | J26: =SUM(J24:J25,J22) -> 1147.8902 | K26: =SUM(K24:K25,K22) -> 1115.8901 | L26: =SUM(L24:L25,L22) -> 1067.5242
A28: Shareholders' Equity | E28: 301.04388 | F28: 279.99125 | G28: 274.92502 | H28: =+Equity!H14 -> 294.96864 | I28: =+Equity!I14 -> 321.531 | J28: =+Equity!J14 -> 357.39898 | K28: =+Equity!K14 -> 401.11189 | L28: =+Equity!L14 -> 451.99872 | N28: Step 8: Link into the Equity Schedule
A29: Total Liabilities and Equity | E29: =SUM(E28,E26) -> 1257.6469 | F29: =SUM(F28,F26) -> 1360.5302 | G29: =SUM(G28,G26) -> 1496.426 | H29: =SUM(H28,H26) -> 1523.4374 | I29: =SUM(I28,I26) -> 1551.7429 | J29: =SUM(J28,J26) -> 1505.2892 | K29: =SUM(K28,K26) -> 1517.002 | L29: =SUM(L28,L26) -> 1519.5229
A31: check | E31: =+E29-E17 -> 0 | F31: =+F29-F17 -> 0 | G31: =+G29-G17 -> 0 | H31: =+H29-H17 -> 0 | I31: =+I29-I17 -> 0 | J31: =+J29-J17 -> 0 | K31: =+K29-K17 -> 3.1832315e-12 | L31: =+L29-L17 -> -1.0572876e-10 | N31: Total Assets - Total Liabilities & Equity
A33: Metrics & Drivers
A34: Net Earnings | E34: ='Income Statement'!E25 -> 72.311185 | F34: =+'Income Statement'!F25 -> 70.855361 | G34: =+'Income Statement'!G25 -> 83.649576 | H34: =+'Income Statement'!H25 -> 94.717136 | I34: =+'Income Statement'!I25 -> 101.01777 | J34: =+'Income Statement'!J25 -> 110.19091 | K34: =+'Income Statement'!K25 -> 118.6687 | L34: =+'Income Statement'!L25 -> 126.52081 | N34: Link to the Income Statement
A35: Cash Ratio | E35: =E10/E22 -> 0.85949057 | F35: =F10/F22 -> 0.90486659 | G35: =G10/G22 -> 0.48252193 | H35: =H10/H22 -> 0.43169063 | I35: =I10/I22 -> 0.19586435 | J35: =J10/J22 -> 0.061982995 | K35: =K10/K22 -> 0.059886951 | L35: =L10/L22 -> 0.058142671 | N35: Cash and Cash Equivalents / Total Current Liabilities
A36: Return on Equity | E36: =+E34/E28 -> 0.24020147 | F36: =+F34/F28 -> 0.25306277 | G36: =+G34/G28 -> 0.30426323 | H36: =+H34/H28 -> 0.32110917 | I36: =+I34/I28 -> 0.31417741 | J36: =+J34/J28 -> 0.30831344 | K36: =+K34/K28 -> 0.29584936 | L36: =+L34/L28 -> 0.2799141 | N36: Net Earnings / Shareholders' Equity
A37: Net Debt | E37: =+E24-E10 -> 313.85812 | F37: =+F24-F10 -> 417.76275 | G37: =+G24-G10 -> 602.09498 | H37: =+H24-H10 -> 587.50304 | I37: =+I24-I10 -> 648.70464 | J37: =+J24-J10 -> 597.41376 | K37: =+K24-K10 -> 551.29686 | L37: =+L24-L10 -> 490.40741 | N37: Total Debt - Cash and Cash Equivalents
A42: Note: Current Maturities of Long-Term Debt has been combined with Total Debt and designated as a long-term liability for training purposes. Cash and Cash
A43: Equivalents includes Restricted Cash and Short-Term Investments.

Sheet Cash Flow Statement
A1: Adventis Air Company Financial Model | L1: This document subject to the Terms of Use
A2: Cash Flow Statement ($ in Millions) | L2: © 2013 Adventis CG Training LLC
E6: Fiscal Year Ended December 31,
E7: 2016A | F7: 2017A | G7: 2018A | H7: 2019E | I7: 2020E | J7: 2021E | K7: 2022E | L7: 2023E | N7: Instructions:
A8: Cash Flow Statement
A10: Net Earnings | H10: =+'Income Statement'!H25 -> 94.717136 | I10: =+'Income Statement'!I25 -> 101.01777 | J10: =+'Income Statement'!J25 -> 110.19091 | K10: =+'Income Statement'!K25 -> 118.6687 | L10: =+'Income Statement'!L25 -> 126.52081 | N10: Step 8: Link into the Income Statement
A11: Depreciation | H11: =-'PP&E'!H12 -> 137.3255 | I11: =-'PP&E'!I12 -> 153.65197 | J11: =-'PP&E'!J12 -> 169.82587 | K11: =-'PP&E'!K12 -> 193.34675 | L11: =-'PP&E'!L12 -> 217.25144 | N11: Step 6: Link into the PP&E Schedule
A12: Change in Working Capital | H12: =-'Working Capital'!H20 -> 25.065093 | I12: =-'Working Capital'!I20 -> 17.366346 | J12: =-'Working Capital'!J20 -> 15.422903 | K12: =-'Working Capital'!K20 -> 11.192469 | L12: =-'Working Capital'!L20 -> 10.002624 | N12: Step 7: Link into the Working Capital Schedule
A13: Cash From Operating Activities | H13: =SUM(H10:H12) -> 257.10773 | I13: =SUM(I10:I12) -> 272.0361 | J13: =SUM(J10:J12) -> 295.43968 | K13: =SUM(K10:K12) -> 323.20791 | L13: =SUM(L10:L12) -> 353.77488
A15: Capital Expenditures | H15: =-'PP&E'!H11 -> -167.84228 | I15: =-'PP&E'!I11 -> -258.78227 | J15: =-'PP&E'!J11 -> -169.82587 | K15: =-'PP&E'!K11 -> -202.13524 | L15: =-'PP&E'!L11 -> -217.25144 | N15: Step 6: Link into the PP&E Schedule
A16: Cash From Investing Activities | H16: =SUM(H15:H15) -> -167.84228 | I16: =SUM(I15:I15) -> -258.78227 | J16: =SUM(J15:J15) -> -169.82587 | K16: =SUM(K15:K15) -> -202.13524 | L16: =SUM(L15:L15) -> -217.25144
A18: Dividends | H18: =+Equity!H12 -> -44.673517 | I18: =+Equity!I12 -> -44.45542 | J18: =+Equity!J12 -> -44.322928 | K18: =+Equity!K12 -> -44.95578 | L18: =+Equity!L12 -> -45.633989 | N18: Step 8: Link into the Equity Schedule
A19: Share Repurchases | H19: =+Equity!H13 -> -30 | I19: =+Equity!I13 -> -30 | J19: =+Equity!J13 -> -30 | K19: =+Equity!K13 -> -30 | L19: =+Equity!L13 -> -30 | N19: Step 8: Link into the Equity Schedule
A20: Change in Revolver | H20: =Debt!H40 -> 0 | I20: =Debt!I40 -> 0 | J20: =Debt!J40 -> 98.471757 | K20: =Debt!K40 -> -26.116895 | L20: =Debt!L40 -> -40.88945 | N20: Step 9: Link into the Debt Schedule
A21: Change in Long-Term Debt | H21: =Debt!H41 -> -20 | I21: =Debt!I41 -> -20 | J21: =Debt!J41 -> -200 | K21: =Debt!K41 -> -20 | L21: =Debt!L41 -> -20 | N21: Step 9: Link into the Debt Schedule
A22: Cash From Financing Activities | H22: =SUM(H18:H21) -> -94.673517 | I22: =SUM(I18:I21) -> -94.45542 | J22: =SUM(J18:J21) -> -175.85117 | K22: =SUM(K18:K21) -> -121.07268 | L22: =SUM(L18:L21) -> -136.52344
A24: Change in Cash | H24: =SUM(H22,H16,H13) -> -5.4080654 | I24: =SUM(I22,I16,I13) -> -81.201598 | J24: =SUM(J22,J16,J13) -> -50.237359 | K24: =SUM(K22,K16,K13) -> 6.2527761e-13 | L24: =SUM(L22,L16,L13) -> -7.1452178e-11
A26: Beginning Cash | H26: =+G27 -> 161.84702 | I26: =+H27 -> 156.43896 | J26: =+I27 -> 75.237359 | K26: =+J27 -> 25 | L26: =+K27 -> 25 | N26: Step 5: Link to the ending balance of the previous year
A27: Ending Cash | G27: =+'Balance Sheet'!G10 -> 161.84702 | H27: =SUM(H26,H24) -> 156.43896 | I27: =SUM(I26,I24) -> 75.237359 | J27: =SUM(J26,J24) -> 25 | K27: =SUM(K26,K24) -> 25 | L27: =SUM(L26,L24) -> 25 | N27: Step 5: Link 2018A into the Balance Sheet
A29: Metrics & Drivers
A30: Free Cash Flow (Levered) | H30: =SUM(H13,H16) -> 89.265452 | I30: =SUM(I13,I16) -> 13.253822 | J30: =SUM(J13,J16) -> 125.61381 | K30: =SUM(K13,K16) -> 121.07268 | L30: =SUM(L13,L16) -> 136.52344 | N30: Cash Flow from Operating Activities - Capital Expenditures
A31: Operating Income | H31: =+'Income Statement'!H14 -> 146.48053 | I31: =+'Income Statement'!I14 -> 153.65197 | J31: =+'Income Statement'!J14 -> 164.73109 | K31: =+'Income Statement'!K14 -> 172.25438 | L31: =+'Income Statement'!L14 -> 179.23244 | N31: Link to the Income Statement
A32: EBITDA | H32: =+H31+H11 -> 283.80603 | I32: =+I31+I11 -> 307.30395 | J32: =+J31+J11 -> 334.55696 | K32: =+K31+K11 -> 365.60113 | L32: =+L31+L11 -> 396.48387 | N32: Operating Income + Depreciation

Sheet PP&E
A1: Adventis Air Company Financial Model | L1: This document subject to the Terms of Use
A2: PP&E Schedule ($ in Millions) | L2: © 2013 Adventis CG Training LLC
E6: Fiscal Year Ended December 31,
E7: 2016A | F7: 2017A | G7: 2018A | H7: 2019E | I7: 2020E | J7: 2021E | K7: 2022E | L7: 2023E | N7: Instructions:
A8: PP&E Schedule
A10: Beginning Balance of PP&E | H10: =+G13 -> 1214.018 | I10: =+H13 -> 1244.5348 | J10: =+I13 -> 1349.6651 | K10: =+J13 -> 1349.6651 | L10: =+K13 -> 1358.4536 | N10: Link to the ending balance of the previous year
A11: Plus: Capital Expenditures | E11: 252.686 | F11: 199.743 | G11: 388.439 | H11: =+H16*H17 -> 167.84228 | I11: =+I16*I17 -> 258.78227 | J11: =+J16*J17 -> 169.82587 | K11: =+K16*K17 -> 202.13524 | L11: =+L16*L17 -> 217.25144 | N11: Revenue x Capital Expenditures as a % Revenue
A12: Less: Depreciation | E12: -98.097 | F12: -110.216 | G12: -121.713 | H12: =-H16*H18 -> -137.3255 | I12: =-I16*I18 -> -153.65197 | J12: =-J16*J18 -> -169.82587 | K12: =-K16*K18 -> -193.34675 | L12: =-L16*L18 -> -217.25144 | N12: Revenue x Depreciation as a % Revenue
A13: Ending Balance of PP&E | G13: =+'Balance Sheet'!G15 -> 1214.018 | H13: =SUM(H10:H12) -> 1244.5348 | I13: =SUM(I10:I12) -> 1349.6651 | J13: =SUM(J10:J12) -> 1349.6651 | K13: =SUM(K10:K12) -> 1358.4536 | L13: =SUM(L10:L12) -> 1358.4536 | N13: Link 2018A into the Balance Sheet
A15: Metrics & Drivers
A16: Revenue | E16: =+'Income Statement'!E10 -> 1253.004 | F16: =+'Income Statement'!F10 -> 1341.587 | G16: =+'Income Statement'!G10 -> 1419.385 | H16: =+'Income Statement'!H10 -> 1525.8389 | I16: =+'Income Statement'!I10 -> 1617.3892 | J16: =+'Income Statement'!J10 -> 1698.2587 | K16: =+'Income Statement'!K10 -> 1757.6977 | L16: =+'Income Statement'!L10 -> 1810.4287 | N16: Link into the Income Statement
A17: Capital Expenditures as a % Revenue | E17: =+E11/E16 -> 0.20166416 | F17: =+F11/F16 -> 0.14888561 | G17: =+G11/G16 -> 0.27366712 | H17: 0.11 | I17: 0.16 | J17: 0.1 | K17: 0.115 | L17: 0.12 | N17: Capital Expenditures / Revenue
A18: Depreciation as a % Revenue | E18: =-E12/E16 -> 0.078289455 | F18: =-F12/F16 -> 0.08215345 | G18: =-G12/G16 -> 0.085750519 | H18: 0.09 | I18: 0.095 | J18: 0.1 | K18: 0.11 | L18: 0.12 | N18: Depreciation / Revenue

Sheet Working Capital
A1: Adventis Air Company Financial Model | L1: This document subject to the Terms of Use
A2: Working Capital Schedule ($ in Millions) | L2: © 2013 Adventis CG Training LLC
E6: Fiscal Year Ended December 31,
E7: 2016A | F7: 2017A | G7: 2018A | H7: 2019E | I7: 2020E | J7: 2021E | K7: 2022E | L7: 2023E | N7: Instructions:
A8: Working Capital Schedule
A10: Accounts Receivable | E10: =+'Balance Sheet'!E11 -> 21.815 | F10: =+'Balance Sheet'!F11 -> 23.667 | G10: =+'Balance Sheet'!G11 -> 24.563 | H10: =H24/H29*H23 -> 27.172473 | I10: =I24/I29*I23 -> 28.802822 | J10: =J24/J29*J23 -> 30.160332 | K10: =K24/K29*K23 -> 31.301466 | L10: =L24/L29*L23 -> 32.24051 | N10: Days Receivable x Revenue / Days
A11: Other Current Assets | E11: =+'Balance Sheet'!E12 -> 37.123 | F11: =+'Balance Sheet'!F12 -> 38.615 | G11: =+'Balance Sheet'!G12 -> 46.482 | H11: =+H25*H$23 -> 45.775166 | I11: =+I25*I$23 -> 48.521676 | J11: =+J25*J$23 -> 50.94776 | K11: =+K25*K$23 -> 52.730932 | L11: =+L25*L$23 -> 54.31286 | N11: Revenue x Other Current Assets as a % of Revenue
A12: Non-Cash Current Assets | E12: =SUM(E10:E11) -> 58.938 | F12: =SUM(F10:F11) -> 62.282 | G12: =SUM(G10:G11) -> 71.045 | H12: =SUM(H10:H11) -> 72.947639 | I12: =SUM(I10:I11) -> 77.324498 | J12: =SUM(J10:J11) -> 81.108092 | K12: =SUM(K10:K11) -> 84.032398 | L12: =SUM(L10:L11) -> 86.55337
A14: Accounts Payable | E14: =+'Balance Sheet'!E19 -> 6.901 | F14: =+'Balance Sheet'!F19 -> 16.01 | G14: =+'Balance Sheet'!G19 -> 20.108 | H14: =+H23*H26 -> 19.072986 | I14: =+I23*I26 -> 20.217365 | J14: =+J23*J26 -> 21.228233 | K14: =+K23*K26 -> 21.971222 | L14: =+L23*L26 -> 22.630358 | N14: Revenue x Accounts Payable as a % of Revenue
A15: Accrued Liabilities | E15: =+'Balance Sheet'!E20 -> 115.131 | F15: =+'Balance Sheet'!F20 -> 96.661 | G15: =+'Balance Sheet'!G20 -> 105.127 | H15: =H23*H27 -> 114.43792 | I15: =I23*I27 -> 121.30419 | J15: =J23*J27 -> 127.3694 | K15: =K23*K27 -> 131.82733 | L15: =L23*L27 -> 135.78215 | N15: Revenue x Accrued Liabilities as a % of Revenue
A16: Other Current Liabilities | E16: =+'Balance Sheet'!E21 -> 197.136 | F16: =+'Balance Sheet'!F21 -> 194.001 | G16: =+'Balance Sheet'!G21 -> 210.184 | H16: =+H28*H$23 -> 228.87583 | I16: =+I28*I$23 -> 242.60838 | J16: =+J28*J$23 -> 254.7388 | K16: =+K28*K$23 -> 263.65466 | L16: =+L28*L$23 -> 271.5643 | N16: Revenue x Other Current Liabilities as a % of Revenue
A17: Non-Debt Current Liabilities | E17: =SUM(E14:E16) -> 319.168 | F17: =SUM(F14:F16) -> 306.672 | G17: =SUM(G14:G16) -> 335.419 | H17: =SUM(H14:H16) -> 362.38673 | I17: =SUM(I14:I16) -> 384.12994 | J17: =SUM(J14:J16) -> 403.33643 | K17: =SUM(K14:K16) -> 417.45321 | L17: =SUM(L14:L16) -> 429.97681
A19: Working Capital | E19: =E12-E17 -> -260.23 | F19: =F12-F17 -> -244.39 | G19: =G12-G17 -> -264.374 | H19: =+H12-H17 -> -289.43909 | I19: =+I12-I17 -> -306.80544 | J19: =+J12-J17 -> -322.22834 | K19: =+K12-K17 -> -333.42081 | L19: =+L12-L17 -> -343.42344 | N19: Non-Cash Current Assets - Non-Debt Current Liabilities
A20: Change in Working Capital | F20: =+F19-E19 -> 15.84 | G20: =+G19-F19 -> -19.984 | H20: =+H19-G19 -> -25.065093 | I20: =+I19-H19 -> -17.366346 | J20: =+J19-I19 -> -15.422903 | K20: =+K19-J19 -> -11.192469 | L20: =+L19-K19 -> -10.002624 | N20: Current Year's Working Capital - Previous Year's Working Capital
A22: Metrics & Drivers
A23: Revenue | E23: =+'Income Statement'!E10 -> 1253.004 | F23: =+'Income Statement'!F10 -> 1341.587 | G23: =+'Income Statement'!G10 -> 1419.385 | H23: =+'Income Statement'!H10 -> 1525.8389 | I23: =+'Income Statement'!I10 -> 1617.3892 | J23: =+'Income Statement'!J10 -> 1698.2587 | K23: =+'Income Statement'!K10 -> 1757.6977 | L23: =+'Income Statement'!L10 -> 1810.4287 | N23: Link into the Income Statement
A24: Days Receivable | E24: =E10/E23*E29 -> 6.3547084 | F24: =F10/F23*F29 -> 6.4566234 | G24: =G10/G23*G29 -> 6.3164645 | H24: 6.5 | I24: 6.5 | J24: 6.5 | K24: 6.5 | L24: 6.5 | N24: Accounts Receivable / Revenue x Days
A25: Other Current Assets as a % Revenue | E25: =E11/E$23 -> 0.0296272 | F25: =F11/F$23 -> 0.028783076 | G25: =G11/G$23 -> 0.032747986 | H25: 0.03 | I25: 0.03 | J25: 0.03 | K25: 0.03 | L25: 0.03 | N25: Other Current Assets / Revenue
A26: Accounts Payable as a % of Revenue | E26: =+E14/E$23 -> 0.0055075642 | F26: =+F14/F$23 -> 0.011933628 | G26: =+G14/G$23 -> 0.014166699 | H26: 0.0125 | I26: 0.0125 | J26: 0.0125 | K26: 0.0125 | L26: 0.0125 | N26: Accounts Payable / Revenue
A27: Accrued Liabilities as a % of Revenue | E27: =E15/E23 -> 0.091883984 | F27: =F15/F23 -> 0.072049744 | G27: =G15/G23 -> 0.074065176 | H27: 0.075 | I27: 0.075 | J27: 0.075 | K27: 0.075 | L27: 0.075 | N27: Accrued Liabilities / Revenue
A28: Other Current Liabilities as a % Revenue | E28: =E16/E$23 -> 0.1573307 | F28: =F16/F$23 -> 0.14460561 | G28: =G16/G$23 -> 0.14808104 | H28: 0.15 | I28: 0.15 | J28: 0.15 | K28: 0.15 | L28: 0.15 | N28: Other Current Liabilities / Revenue
A29: Days | E29: 365 | F29: 366 | G29: 365 | H29: 365 | I29: 365 | J29: 366 | K29: 365 | L29: 365

Sheet Equity
A1: Adventis Air Company Financial Model | L1: This document subject to the Terms of Use
A2: Equity Schedule ($ in Millions) | L2: © 2013 Adventis CG Training LLC
E6: Fiscal Year Ended December 31,
E7: 2016A | F7: 2017A | G7: 2018A | H7: 2019E | I7: 2020E | J7: 2021E | K7: 2022E | L7: 2023E | N7: Instructions:
A8: Equity Schedule
A10: Beginning Balance of Equity | H10: =+G14 -> 274.92502 | I10: =+H14 -> 294.96864 | J10: =+I14 -> 321.531 | K10: =+J14 -> 357.39898 | L10: =+K14 -> 401.11189 | N10: Link to the ending balance of the previous year
A11: Plus: Net Earnings | H11: =+'Income Statement'!H25 -> 94.717136 | I11: =+'Income Statement'!I25 -> 101.01777 | J11: =+'Income Statement'!J25 -> 110.19091 | K11: =+'Income Statement'!K25 -> 118.6687 | L11: =+'Income Statement'!L25 -> 126.52081 | N11: Link into the Income Statement
A12: Less: Dividends | H12: =-H41 -> -44.673517 | I12: =-I41 -> -44.45542 | J12: =-J41 -> -44.322928 | K12: =-K41 -> -44.95578 | L12: =-L41 -> -45.633989 | N12: Link into the Dividend Schedule
A13: Less: Share Repurchases | H13: =-H32 -> -30 | I13: =-I32 -> -30 | J13: =-J32 -> -30 | K13: =-K32 -> -30 | L13: =-L32 -> -30 | N13: Link into the Share Repurchase Schedule
A14: Ending Balance of Equity | G14: =+'Balance Sheet'!G28 -> 274.92502 | H14: =SUM(H10:H13) -> 294.96864 | I14: =SUM(I10:I13) -> 321.531 | J14: =SUM(J10:J13) -> 357.39898 | K14: =SUM(K10:K13) -> 401.11189 | L14: =SUM(L10:L13) -> 451.99872 | N14: Link 2018A into the Balance Sheet
A16: Common Stock Schedule
A18: Beginning Balance of Shares Outstanding | E18: 17.413 | F18: =+E21 -> 16.195723 | G18: =+F21 -> 15.27509 | H18: =+G21 -> 14.568284 | I18: =+H21 -> 14.253341 | J18: =+I21 -> 13.972323 | K18: =+J21 -> 13.729507 | L18: =+K21 -> 13.516421
A19: No. of Shares Repurchased | E19: -1.2818339 | F19: -1.0438757 | G19: -0.77467342 | H19: =-H30 -> -0.41494302 | I19: =-I30 -> -0.38101751 | J19: =-J30 -> -0.34281614 | K19: =-K30 -> -0.31308626 | L19: =-L30 -> -0.28931843 | N19: Link to row 30
A20: No. of Shares Issued | E20: 0.064556634 | F20: 0.12324318 | G20: 0.067866754 | H20: 0.1 | I20: 0.1 | J20: 0.1 | K20: 0.1 | L20: 0.1
A21: Ending Balance of Shares Outstanding | E21: =SUM(E18:E20) -> 16.195723 | F21: =SUM(F18:F20) -> 15.27509 | G21: =SUM(G18:G20) -> 14.568284 | H21: =SUM(H18:H20) -> 14.253341 | I21: =SUM(I18:I20) -> 13.972323 | J21: =SUM(J18:J20) -> 13.729507 | K21: =SUM(K18:K20) -> 13.516421 | L21: =SUM(L18:L20) -> 13.327102
A23: Metrics & Drivers
A24: Average Common Shares Outstanding | E24: 16.804361 | F24: 15.735406 | G24: 14.921687 | H24: =AVERAGE(H21,H18) -> 14.410812 | I24: =AVERAGE(I21,I18) -> 14.112832 | J24: =AVERAGE(J21,J18) -> 13.850915 | K24: =AVERAGE(K21,K18) -> 13.622964 | L24: =AVERAGE(L21,L18) -> 13.421761 | N24: =Average (Beginning Balance of Shares Outstanding, Ending Balance of Shares Outstanding)
A25: Net Earnings | E25: =+'Income Statement'!E25 -> 72.311185 | F25: =+'Income Statement'!F25 -> 70.855361 | G25: =+'Income Statement'!G25 -> 83.649576 | H25: =+'Income Statement'!H25 -> 94.717136 | I25: =+'Income Statement'!I25 -> 101.01777 | J25: =+'Income Statement'!J25 -> 110.19091 | K25: =+'Income Statement'!K25 -> 118.6687 | L25: =+'Income Statement'!L25 -> 126.52081 | N25: Link into the Income Statement
A26: Basic Earnings per Share | E26: =+E25/E24 -> 4.3031201 | F26: =+F25/F24 -> 4.5029254 | G26: =+G25/G24 -> 5.6059061 | H26: =+H25/H24 -> 6.5726439 | I26: =+I25/I24 -> 7.1578671 | J26: =+J25/J24 -> 7.9554968 | K26: =+K25/K24 -> 8.7109309 | L26: =+L25/L24 -> 9.4265433 | N26: Net Earnings / Average Common Shares Outstanding
A28: Share Repurchases Schedule
A30: No. of Shares Repurchased | E30: =-E19 -> 1.2818339 | F30: =-F19 -> 1.0438757 | G30: =-G19 -> 0.77467342 | H30: =H32/H31 -> 0.41494302 | I30: =I32/I31 -> 0.38101751 | J30: =J32/J31 -> 0.34281614 | K30: =K32/K31 -> 0.31308626 | L30: =L32/L31 -> 0.28931843 | N30: Link to row 19; Share Repurchases ($) / Average Price Paid per Share
A31: x Average Price Paid per Share | E31: =+E32/E30 -> 46.35 | F31: =+F32/F30 -> 50.21 | G31: =+G32/G30 -> 61.24 | H31: =+H35*H26 -> 72.299083 | I31: =+I35*I26 -> 78.736539 | J31: =+J35*J26 -> 87.510465 | K31: =+K35*K26 -> 95.82024 | L31: =+L35*L26 -> 103.69198 | N31: Share Repurchases ($) / No. of Shares Repurchased; P/E Multiple * Basic Earnings per Share
A32: Share Repurchases ($) | E32: 59.413 | F32: 52.413 | G32: 47.441 | H32: 30 | I32: 30 | J32: 30 | K32: 30 | L32: 30
A34: Metrics & Drivers
A35: P/E Multiple | E35: =+E31/E26 -> 10.771254 | F35: =+F31/F26 -> 11.150529 | G35: =+G31/G26 -> 10.924193 | H35: 11 | I35: 11 | J35: 11 | K35: 11 | L35: 11 | N35: Average Price Paid per Share / Basic Earnings per Share
A37: Dividends Schedule
A39: Average Common Shares Outstanding | E39: =+E24 -> 16.804361 | F39: =+F24 -> 15.735406 | G39: =+G24 -> 14.921687 | H39: =+H24 -> 14.410812 | I39: =+I24 -> 14.112832 | J39: =+J24 -> 13.850915 | K39: =+K24 -> 13.622964 | L39: =+L24 -> 13.421761 | N39: Link to row 24
A40: x Dividends per Share | E40: =+E41/E39 -> 2.6009498 | F40: =+F41/F39 -> 2.8266191 | G40: =+G41/G39 -> 3.0076894 | H40: 3.1 | I40: 3.15 | J40: 3.2 | K40: 3.3 | L40: 3.4 | N40: Dividends ($) / Average Common Shares Outstanding
A41: Dividends ($) | E41: 43.7073 | F41: 44.478 | G41: 44.8798 | H41: =+H39*H40 -> 44.673517 | I41: =+I39*I40 -> 44.45542 | J41: =+J39*J40 -> 44.322928 | K41: =+K39*K40 -> 44.95578 | L41: =+L39*L40 -> 45.633989 | N41: Average Common Shares Outstanding x Dividends per Share
A43: Metrics & Drivers
A44: Dividend Yield | E44: =+E40/E31 -> 0.056115421 | F44: =+F40/F31 -> 0.056295938 | G44: =+G40/G31 -> 0.049113152 | H44: =+H40/H31 -> 0.042877446 | I44: =+I40/I31 -> 0.040006839 | J44: =+J40/J31 -> 0.036567055 | K44: =+K40/K31 -> 0.034439488 | L44: =+L40/L31 -> 0.032789422 | N44: Dividend per Share / Average Price Paid per Share

Sheet Debt
A1: Adventis Air Company Financial Model | L1: This document subject to the Terms of Use
A2: Debt Schedule ($ in Millions) | L2: © 2013 Adventis CG Training LLC
E6: Fiscal Year Ended December 31,
E7: 2016A | F7: 2017A | G7: 2018A | H7: 2019E | I7: 2020E | J7: 2021E | K7: 2022E | L7: 2023E | N7: Instructions:
A8: Beginning Debt
A10: Revolver Beginning Balance | H10: =+G35 -> 0 | I10: =+H35 -> 0 | J10: =+I35 -> 0 | K10: =+J35 -> 98.471757 | L10: =+K35 -> 72.354861 | N10: Link to the Ending Balance of the previous year
A11: Long-Term Debt Beginning Balance | H11: =+G36 -> 763.942 | I11: =+H36 -> 743.942 | J11: =+I36 -> 723.942 | K11: =+J36 -> 523.942 | L11: =+K36 -> 503.942 | N11: Link to the Ending Balance of the previous year
A12: Total Beginning Debt Balance | H12: =SUM(H10:H11) -> 763.942 | I12: =SUM(I10:I11) -> 743.942 | J12: =SUM(J10:J11) -> 723.942 | K12: =SUM(K10:K11) -> 622.41376 | L12: =SUM(L10:L11) -> 576.29686
A14: Debt Pay Down and Issuance
A16: Beginning Cash Balance | H16: =+'Balance Sheet'!G10 -> 161.84702 | I16: =+'Balance Sheet'!H10 -> 156.43896 | J16: =+'Balance Sheet'!I10 -> 75.237359 | K16: =+'Balance Sheet'!J10 -> 25 | L16: =+'Balance Sheet'!K10 -> 25 | N16: Link into the Balance Sheet
A17: Cash From Operating Activities | H17: =+'Cash Flow Statement'!H13 -> 257.10773 | I17: =+'Cash Flow Statement'!I13 -> 272.0361 | J17: =+'Cash Flow Statement'!J13 -> 295.43968 | K17: =+'Cash Flow Statement'!K13 -> 323.20791 | L17: =+'Cash Flow Statement'!L13 -> 353.77488 | N17: Link into the Cash Flow Statement
A18: Cash From Investing Activities | H18: =+'Cash Flow Statement'!H16 -> -167.84228 | I18: =+'Cash Flow Statement'!I16 -> -258.78227 | J18: =+'Cash Flow Statement'!J16 -> -169.82587 | K18: =+'Cash Flow Statement'!K16 -> -202.13524 | L18: =+'Cash Flow Statement'!L16 -> -217.25144 | N18: Link into the Cash Flow Statement
A19: Dividends | H19: =-Equity!H41 -> -44.673517 | I19: =-Equity!I41 -> -44.45542 | J19: =-Equity!J41 -> -44.322928 | K19: =-Equity!K41 -> -44.95578 | L19: =-Equity!L41 -> -45.633989 | N19: Link into the Cash Flow Statement
A20: Share Repurchases | H20: =-Equity!H32 -> -30 | I20: =-Equity!I32 -> -30 | J20: =-Equity!J32 -> -30 | K20: =-Equity!K32 -> -30 | L20: =-Equity!L32 -> -30 | N20: Link into the Cash Flow Statement
A21: Long-Term Debt Paydown (Scheduled) | H21: -20 | I21: -20 | J21: -200 | K21: -20 | L21: -20
A22: Less: Minimum Cash Balance | H22: -25 | I22: -25 | J22: -25 | K22: -25 | L22: -25
A23: Total Cash Available (Required) | H23: =SUM(H16:H22) -> 131.43896 | I23: =SUM(I16:I22) -> 50.237359 | J23: =SUM(J16:J22) -> -98.471757 | K23: =SUM(K16:K22) -> 26.116895 | L23: =SUM(L16:L22) -> 40.88945
A25: Revolver Issued | H25: =IF(H23<0,-H23,0) -> 0 | I25: =IF(I23<0,-I23,0) -> 0 | J25: =IF(J23<0,-J23,0) -> 98.471757 | K25: =IF(K23<0,-K23,0) -> 0 | L25: =IF(L23<0,-L23,0) -> 0 | N25: =IF(H23<0,-H23,0)
A26: Long-Term Debt Issued | H26: 0 | I26: 0 | J26: 0 | K26: 0 | L26: 0
A27: Total Cash Available | H27: =SUM(H25:H26,H23) -> 131.43896 | I27: =SUM(I25:I26,I23) -> 50.237359 | J27: =SUM(J25:J26,J23) -> 0 | K27: =SUM(K25:K26,K23) -> 26.116895 | L27: =SUM(L25:L26,L23) -> 40.88945
A29: Revolver Paydown | H29: =-IF(H27>0,MIN(H10,H27),0) -> 0 | I29: =-IF(I27>0,MIN(I10,I27),0) -> 0 | J29: =-IF(J27>0,MIN(J10,J27),0) -> 0 | K29: =-IF(K27>0,MIN(K10,K27),0) -> -26.116895 | L29: =-IF(L27>0,MIN(L10,L27),0) -> -40.88945 | N29: =-IF(H27>0,MIN(H10,H27),0)
A30: Long-Term Debt Paydown | H30: =+H21 -> -20 | I30: =+I21 -> -20 | J30: =+J21 -> -200 | K30: =+K21 -> -20 | L30: =+L21 -> -20 | N30: Link into row 21
A31: Total Debt Paydown | H31: =SUM(H29:H30) -> -20 | I31: =SUM(I29:I30) -> -20 | J31: =SUM(J29:J30) -> -200 | K31: =SUM(K29:K30) -> -46.116895 | L31: =SUM(L29:L30) -> -60.88945
A33: Ending Debt
A35: Revolver Ending Balance | G35: 0 | H35: =+H29+H10+H25 -> 0 | I35: =+I29+I10+I25 -> 0 | J35: =+J29+J10+J25 -> 98.471757 | K35: =+K29+K10+K25 -> 72.354861 | L35: =+L29+L10+L25 -> 31.465411 | N35: Beginning Revolver Balance + Revolver Issued + Revolver Paydown
A36: Long-Term Debt Ending Balance | G36: 763.942 | H36: =+H30+H11+H26 -> 743.942 | I36: =+I30+I11+I26 -> 723.942 | J36: =+J30+J11+J26 -> 523.942 | K36: =+K30+K11+K26 -> 503.942 | L36: =+L30+L11+L26 -> 483.942 | N36: Beginning Long-Term Debt Balance + Long-Term Debt Issued + Long-Term Debt Paydown
A37: Total Ending Debt Balance | G37: =SUM(G35:G36) -> 763.942 | H37: =SUM(H35:H36) -> 743.942 | I37: =SUM(I35:I36) -> 723.942 | J37: =SUM(J35:J36) -> 622.41376 | K37: =SUM(K35:K36) -> 576.29686 | L37: =SUM(L35:L36) -> 515.40741
A39: Metrics & Drivers
A40: Change in Revolver | H40: =H25+H29 -> 0 | I40: =I25+I29 -> 0 | J40: =J25+J29 -> 98.471757 | K40: =K25+K29 -> -26.116895 | L40: =L25+L29 -> -40.88945 | N40: Revolver Issued + Revolver Paydown
A41: Change in Long-Term Debt | H41: =H26+H30 -> -20 | I41: =I26+I30 -> -20 | J41: =J26+J30 -> -200 | K41: =K26+K30 -> -20 | L41: =L26+L30 -> -20 | N41: Long-Term Debt Issued + Long-Term Debt Paydown
A42: EBITDA | H42: =+'Cash Flow Statement'!H32 -> 283.80603 | I42: =+'Cash Flow Statement'!I32 -> 307.30395 | J42: =+'Cash Flow Statement'!J32 -> 334.55696 | K42: =+'Cash Flow Statement'!K32 -> 365.60113 | L42: =+'Cash Flow Statement'!L32 -> 396.48387 | N42: Link to the Cash Flow Statement
A43: Shareholders' Equity | H43: =+'Balance Sheet'!H28 -> 294.96864 | I43: =+'Balance Sheet'!I28 -> 321.531 | J43: =+'Balance Sheet'!J28 -> 357.39898 | K43: =+'Balance Sheet'!K28 -> 401.11189 | L43: =+'Balance Sheet'!L28 -> 451.99872 | N43: Link to the Balance Sheet
A44: Debt / EBITDA | H44: =+H37/H42 -> 2.6213044 | I44: =+I37/I42 -> 2.3557849 | J44: =+J37/J42 -> 1.8604119 | K44: =+K37/K42 -> 1.5762995 | L44: =+L37/L42 -> 1.2999455 | N44: Total Ending Debt Balance / EBITDA
A45: Debt-to-Equity Ratio | H45: =+H37/H43 -> 2.5221054 | I45: =+I37/I43 -> 2.2515465 | J45: =+J37/J43 -> 1.7415096 | K45: =+K37/K43 -> 1.4367484 | L45: =+L37/L43 -> 1.1402851 | N45: Total Ending Debt Balance / Shareholders' Equity

Sheet Interest
A1: Adventis Air Company Financial Model | L1: This document subject to the Terms of Use
A2: Interest Schedule ($ in Millions) | L2: © 2013 Adventis CG Training LLC
E6: Fiscal Year Ended December 31,
E7: 2016A | F7: 2017A | G7: 2018A | H7: 2019E | I7: 2020E | J7: 2021E | K7: 2022E | L7: 2023E | N7: Instructions:
A8: Interest Expense Schedule
A10: Revolver Average Balance | H10: =AVERAGE(H23,H25) -> 0 | I10: =AVERAGE(I23,I25) -> 0 | J10: =AVERAGE(J23,J25) -> 49.235878 | K10: =AVERAGE(K23,K25) -> 85.413309 | L10: =AVERAGE(L23,L25) -> 51.910136 | N10: =Average(Revolver Beginning Balance,Revolver Ending Balance)
A11: Long-Term Debt Average Balance | H11: =AVERAGE(H24,H26) -> 753.942 | I11: =AVERAGE(I24,I26) -> 733.942 | J11: =AVERAGE(J24,J26) -> 623.942 | K11: =AVERAGE(K24,K26) -> 513.942 | L11: =AVERAGE(L24,L26) -> 493.942 | N11: =Average(Long-Term Debt Beginning Balance,Long-Term Debt Ending Balance)
A12: Average Debt Balance | H12: =SUM(H10:H11) -> 753.942 | I12: =SUM(I10:I11) -> 733.942 | J12: =SUM(J10:J11) -> 673.17788 | K12: =SUM(K10:K11) -> 599.35531 | L12: =SUM(L10:L11) -> 545.85214
A14: Revolver Interest Rate | H14: 0.03 | I14: 0.03 | J14: 0.03 | K14: 0.03 | L14: 0.03
A15: Long-Term Debt Interest Rate | H15: 0.035 | I15: 0.035 | J15: 0.035 | K15: 0.035 | L15: 0.035
A16: Average Interest Rate | H16: =H20/H12 -> 0.035 | I16: =IF(ISNUMBER(+I20/I12),+I20/I12,0) -> 0.035 | J16: =IF(ISNUMBER(+J20/J12),+J20/J12,0) -> 0.034634303 | K16: =IF(ISNUMBER(+K20/K12),+K20/K12,0) -> 0.034287457 | L16: =IF(ISNUMBER(+L20/L12),+L20/L12,0) -> 0.034524504 | N16: Total Interest Expense / Average Debt Balance
A18: Revolver Interest Expense | H18: =+H14*H10 -> 0 | I18: =+I14*I10 -> 0 | J18: =+J14*J10 -> 1.4770763 | K18: =+K14*K10 -> 2.5623993 | L18: =+L14*L10 -> 1.5573041 | N18: Revolver Average Balance x Revolver Interest Rate
A19: Long-Term Debt Interest Expense | H19: =+H15*H11 -> 26.38797 | I19: =+I15*I11 -> 25.68797 | J19: =+J15*J11 -> 21.83797 | K19: =+K15*K11 -> 17.98797 | L19: =+L15*L11 -> 17.28797 | N19: Long-Term Debt Average Balance x Long-Term Debt Interest Rate
A20: Total Interest Expense | H20: =SUM(H18:H19) -> 26.38797 | I20: =SUM(I18:I19) -> 25.68797 | J20: =SUM(J18:J19) -> 23.315046 | K20: =SUM(K18:K19) -> 20.550369 | L20: =SUM(L18:L19) -> 18.845274
A22: Metrics & Drivers
A23: Revolver Beginning Balance | H23: =Debt!H10 -> 0 | I23: =Debt!I10 -> 0 | J23: =Debt!J10 -> 0 | K23: =Debt!K10 -> 98.471757 | L23: =Debt!L10 -> 72.354861 | N23: Link into the Debt Schedule
A24: Long-Term Debt Beginning Balance | H24: =Debt!H11 -> 763.942 | I24: =Debt!I11 -> 743.942 | J24: =Debt!J11 -> 723.942 | K24: =Debt!K11 -> 523.942 | L24: =Debt!L11 -> 503.942 | N24: Link into the Debt Schedule
A25: Revolver Ending Balance | H25: =Debt!H35 -> 0 | I25: =Debt!I35 -> 0 | J25: =Debt!J35 -> 98.471757 | K25: =Debt!K35 -> 72.354861 | L25: =Debt!L35 -> 31.465411 | N25: Link into the Debt Schedule
A26: Long-Term Debt Ending Balance | H26: =Debt!H36 -> 743.942 | I26: =Debt!I36 -> 723.942 | J26: =Debt!J36 -> 523.942 | K26: =Debt!K36 -> 503.942 | L26: =Debt!L36 -> 483.942 | N26: Link into the Debt Schedule
A28: Interest Income Schedule
A30: Average Cash Balance | H30: =AVERAGE(H35:H36) -> 159.14299 | I30: =AVERAGE(I35:I36) -> 115.83816 | J30: =AVERAGE(J35:J36) -> 50.118679 | K30: =AVERAGE(K35:K36) -> 25 | L30: =AVERAGE(L35:L36) -> 25 | N30: =Average(Cash Beginning Balance,Cash Ending Balance)
A31: Interest Rate on Cash | H31: 0.03 | I31: 0.03 | J31: 0.03 | K31: 0.03 | L31: 0.03
A32: Total Interest Income | H32: =H30*H31 -> 4.7742897 | I32: =I30*I31 -> 3.4751447 | J32: =J30*J31 -> 1.5035604 | K32: =K30*K31 -> 0.75 | L32: =L30*L31 -> 0.75
A34: Metrics & Drivers
A35: Cash Beginning Balance | H35: =+'Cash Flow Statement'!H26 -> 161.84702 | I35: =+'Cash Flow Statement'!I26 -> 156.43896 | J35: =+'Cash Flow Statement'!J26 -> 75.237359 | K35: =+'Cash Flow Statement'!K26 -> 25 | L35: =+'Cash Flow Statement'!L26 -> 25 | N35: Link into the Cash Flow Statement
A36: Cash Ending Balance | H36: =+'Cash Flow Statement'!H27 -> 156.43896 | I36: =+'Cash Flow Statement'!I27 -> 75.237359 | J36: =+'Cash Flow Statement'!J27 -> 25 | K36: =+'Cash Flow Statement'!K27 -> 25 | L36: =+'Cash Flow Statement'!L27 -> 25 | N36: Link into the Cash Flow Statement

Sheet Public Comps
A1: Valuation Module | P1: This document subject to the Terms of Use
A2: Public Comparables Analysis ($ in Millions) | P2: © 2013 Adventis CG Training LLC
K7: Enterprise Value /
C8: Share | D8: Shares | E8: Market | F8: Net | G8: Enterprise | H8: Sales CAGR | I8: EBITDA Margin | K8: EBITDA | M8: Sales | O8: Price / Earnings | S8: EBITDA | U8: Sales | X8: EPS | Z8: Total
C9: Price | D9: Outstanding | E9: Cap | F9: Debt | G9: Value | H9: 18A-20E | I9: 2019E | J9: 2020E | K9: 2019E | L9: 2020E | M9: 2019E | N9: 2020E | O9: 2019E | P9: 2020E | R9: Ticker | S9: 2019E | T9: 2020E | U9: 2018A | V9: 2019E | W9: 2020E | X9: 2019E | Y9: 2020E | Z9: Debt | AA9: Cash
A11: Delta Air Lines | C11: 57.71 | D11: 676.55 | E11: =+D11*C11 -> 39043.7 | F11: =+Z11-AA11 -> 14363 | G11: =+E11+F11 -> 53406.7 | H11: =(W11/U11)^(1/2)-1 -> 0.045395827 | I11: =S11/V11 -> 0.18717525 | J11: =T11/W11 -> 0.18500434 | K11: =+$G11/S11 -> 6.1433499 | L11: =+$G11/T11 -> 5.9442601 | M11: =+$G11/V11 -> 1.149883 | N11: =+$G11/W11 -> 1.0997139 | O11: =+C11/X11 -> 8.9279084 | P11: =+C11/Y11 -> 8.4149898 | R11: DAL | S11: 8693.4167 | T11: 8984.5833 | U11: 44438 | V11: 46445.333 | W11: 48564.176 | X11: 6.464 | Y11: 6.858 | Z11: 16131 | AA11: 1768
A12: Southwest Airlines | C12: 51.94 | D12: 552.69 | E12: =+D12*C12 -> 28706.719 | F12: =+Z12-AA12 -> -1029 | G12: =+E12+F12 -> 27677.719 | H12: =(W12/U12)^(1/2)-1 -> 0.064422381 | I12: =S12/V12 -> 0.20181967 | J12: =T12/W12 -> 0.20151702 | K12: =+$G12/S12 -> 5.8995457 | L12: =+$G12/T12 -> 5.5189868 | M12: =+$G12/V12 -> 1.1906444 | N12: =+$G12/W12 -> 1.1121698 | O12: =+C12/X12 -> 10.983295 | P12: =+C12/Y12 -> 9.9387677 | R12: LUV | S12: 4691.5 | T12: 5015 | U12: 21965 | V12: 23246 | W12: 24886.235 | X12: 4.729 | Y12: 5.226 | Z12: 2660 | AA12: 3689
A13: American Airlines | C13: 33.88 | D13: 449.06 | E13: =+D13*C13 -> 15214.153 | F13: =+Z13-AA13 -> 28575 | G13: =+E13+F13 -> 43789.153 | H13: =(W13/U13)^(1/2)-1 -> 0.043629751 | I13: =S13/V13 -> 0.1408603 | J13: =T13/W13 -> 0.13590019 | K13: =+$G13/S13 -> 6.6808162 | L13: =+$G13/T13 -> 6.6419194 | M13: =+$G13/V13 -> 0.94106174 | N13: =+$G13/W13 -> 0.90263813 | O13: =+C13/X13 -> 6.0248963 | P13: =+C13/Y13 -> 5.8967318 | R13: AAL | S13: 6554.4615 | T13: 6592.8462 | U13: 44541 | V13: 46531.647 | W13: 48512.412 | X13: 5.6233333 | Y13: 5.7455556 | Z13: 33335 | AA13: 4760
A14: United Continential Holdings | C14: 84.58 | D14: 266.73 | E14: =+D14*C14 -> 22560.023 | F14: =+Z14-AA14 -> 10778 | G14: =+E14+F14 -> 33338.023 | H14: =(W14/U14)^(1/2)-1 -> 0.054668119 | I14: =S14/V14 -> 0.15617223 | J14: =T14/W14 -> 0.15318654 | K14: =+$G14/S14 -> 4.9174148 | L14: =+$G14/T14 -> 4.7370287 | M14: =+$G14/V14 -> 0.76796362 | N14: =+$G14/W14 -> 0.72564902 | O14: =+C14/X14 -> 7.6432315 | P14: =+C14/Y14 -> 7.0636379 | R14: UAL | S14: 6779.5833 | T14: 7037.75 | U14: 41303 | V14: 43410.941 | W14: 45942.353 | X14: 11.066 | Y14: 11.974 | Z14: 14728 | AA14: 3950
A15: Alaska Air Group | C15: 58.33 | D15: 123.61 | E15: =+D15*C15 -> 7210.1713 | F15: =+Z15-AA15 -> 874 | G15: =+E15+F15 -> 8084.1713 | H15: =(W15/U15)^(1/2)-1 -> 0.056155607 | I15: =S15/V15 -> 0.17309935 | J15: =T15/W15 -> 0.17539836 | K15: =+$G15/S15 -> 5.378179 | L15: =+$G15/T15 -> 4.9999292 | M15: =+$G15/V15 -> 0.9309593 | N15: =+$G15/W15 -> 0.87697938 | O15: =+C15/X15 -> 9.7476604 | P15: =+C15/Y15 -> 8.8782344 | R15: ALK | S15: 1503.1429 | T15: 1616.8571 | U15: 8264 | V15: 8683.7 | W15: 9218.2 | X15: 5.984 | Y15: 6.57 | Z15: 2110 | AA15: 1236
A16: JetBlue Airways | C16: 16.34 | D16: 300.95 | E16: =+D16*C16 -> 4917.523 | F16: =+Z16-AA16 -> 1212 | G16: =+E16+F16 -> 6129.523 | H16: =(W16/U16)^(1/2)-1 -> 0.076461583 | I16: =S16/V16 -> 0.1681426 | J16: =T16/W16 -> 0.17530145 | K16: =+$G16/S16 -> 4.4507138 | L16: =+$G16/T16 -> 3.9402951 | M16: =+$G16/V16 -> 0.74835459 | N16: =+$G16/W16 -> 0.69073943 | O16: =+C16/X16 -> 8.978022 | P16: =+C16/Y16 -> 7.6489175 | R16: JBLU | S16: 1377.2 | T16: 1555.6 | U16: 7658 | V16: 8190.6667 | W16: 8873.8571 | X16: 1.82 | Y16: 2.13625 | Z16: 2099 | AA16: 887
A17: Spirit Airlines | C17: 54.7 | D17: 68.33 | E17: =+D17*C17 -> 3737.651 | F17: =+Z17-AA17 -> 1079.254 | G17: =+E17+F17 -> 4816.905 | H17: =(W17/U17)^(1/2)-1 -> 0.16379577 | I17: =S17/V17 -> 0.22006324 | J17: =T17/W17 -> 0.21075108 | K17: =+$G17/S17 -> 5.5815817 | L17: =+$G17/T17 -> 5.0782016 | M17: =+$G17/V17 -> 1.2283009 | N17: =+$G17/W17 -> 1.0702365 | O17: =+C17/X17 -> 8.4495076 | P17: =+C17/Y17 -> 8.0515179 | R17: SAVE | S17: 863 | T17: 948.54545 | U17: 3323.034 | V17: 3921.6 | W17: 4500.7857 | X17: 6.47375 | Y17: 6.79375 | Z17: 2186.776 | AA17: 1107.522
A18: Allegiant Travel | C18: 133.87 | D18: 16.09 | E18: =+D18*C18 -> 2153.9683 | F18: =+Z18-AA18 -> 861.62 | G18: =+E18+F18 -> 3015.5883 | H18: =(W18/U18)^(1/2)-1 -> 0.10105967 | I18: =S18/V18 -> 0.27449186 | J18: =T18/W18 -> 0.26694286 | K18: =+$G18/S18 -> 6.0101411 | L18: =+$G18/T18 -> 5.5883035 | M18: =+$G18/V18 -> 1.6497348 | N18: =+$G18/W18 -> 1.4917578 | O18: =+C18/X18 -> 10.062387 | P18: =+C18/Y18 -> 9.1328967 | R18: ALGT | S18: 501.75 | T18: 539.625 | U18: 1667.447 | V18: 1827.9231 | W18: 2021.5 | X18: 13.304 | Y18: 14.658 | Z18: 1272 | AA18: 410.38
A19: Hawaiian Holdings | C19: 27.55 | D19: 48.42 | E19: =+D19*C19 -> 1333.971 | F19: =+Z19-AA19 -> 208.963 | G19: =+E19+F19 -> 1542.934 | H19: =(W19/U19)^(1/2)-1 -> 0.020925168 | I19: =S19/V19 -> 0.1468691 | J19: =T19/W19 -> 0.13897342 | K19: =+$G19/S19 -> 3.7204747 | L19: =+$G19/T19 -> 3.7540973 | M19: =+$G19/V19 -> 0.54642278 | N19: =+$G19/W19 -> 0.52171975 | O19: =+C19/X19 -> 6.3528055 | P19: =+C19/Y19 -> 5.9247312 | R19: HA | S19: 414.71429 | T19: 411 | U19: 2837.411 | V19: 2823.7 | W19: 2957.4 | X19: 4.3366667 | Y19: 4.65 | Z19: 709.781 | AA19: 500.818
A21: Average | E21: =AVERAGE(E11:E19) -> 13875.32 | F21: =AVERAGE(F11:F19) -> 6324.7597 | G21: =AVERAGE(G11:G19) -> 20200.08 | H21: =AVERAGE(H11:H19) -> 0.069612653 | I21: =AVERAGE(I11:I19) -> 0.1854104 | J21: =AVERAGE(J11:J19) -> 0.18255281 | K21: =AVERAGE(K11:K19) -> 5.4202463 | L21: =AVERAGE(L11:L19) -> 5.1336691 | ... P21: =AVERAGE(P11:P19) -> 7.8833805
A22: Median | E22: =MEDIAN(E11:E19) -> 7210.1713 | F22: =MEDIAN(F11:F19) -> 1079.254 | G22: =MEDIAN(G11:G19) -> 8084.1713 | H22: =MEDIAN(H11:H19) -> 0.056155607 | I22: =MEDIAN(I11:I19) -> 0.17309935 | J22: =MEDIAN(J11:J19) -> 0.17539836 | K22: =MEDIAN(K11:K19) -> 5.5815817 | L22: =MEDIAN(L11:L19) -> 5.0782016 | ... P22: =MEDIAN(P11:P19) -> 8.0515179
A25: Adventis Air | C25: 63.24 | D25: =+Equity!G21 -> 14.568284 | E25: =+D25*C25 -> 921.29825 | F25: =Z25-AA25 -> 602.09498 | G25: =+E25+F25 -> 1523.3932 | H25: =(W25/U25)^(1/2)-1 -> 0.067473653 | I25: =S25/V25 -> 0.186 | J25: =T25/W25 -> 0.19 | K25: =+$G25/S25 -> 5.3677268 | L25: =+$G25/T25 -> 4.9572849 | M25: =+$G25/V25 -> 0.99839718 | N25: =+$G25/W25 -> 0.94188413 | O25: =+C25/X25 -> 9.6216988 | P25: =+C25/Y25 -> 8.8350341 | R25: ADVA | S25: ='Cash Flow Statement'!H32 -> 283.80603 | T25: ='Cash Flow Statement'!I32 -> 307.30395 | U25: ='Income Statement'!G10 -> 1419.385 | V25: ='Income Statement'!H10 -> 1525.8389 | W25: ='Income Statement'!I10 -> 1617.3892 | X25: =Equity!H26 -> 6.5726439 | Y25: =Equity!I26 -> 7.1578671 | Z25: =Debt!G37 -> 763.942 | AA25: ='Balance Sheet'!G10 -> 161.84702
A47: Source: Yahoo Finance and Bloomberg as of 4/8/2019. Shares Outstanding represent basic shares outstanding.

Sheet M&A Comps
A1: Valuation Module | I1: This document subject to the Terms of Use
A2: Acquisition Comparables Analysis ($ in Millions) | I2: © 2013 Adventis CG Training LLC
D8: Transaction | E8: LTM | F8: LTM | G8: Transaction Value | I8: EBITDA
A9: Target | B9: Buyer | C9: Date | D9: Value | E9: EBITDA | F9: Sales | G9: LTM EBITDA | H9: LTM Sales | I9: Margin
A11: Virgin America | B11: Alaska Air Group | C11: 42464 | D11: 2289.706 | E11: 195.87548 | F11: 1529.584 | G11: =D11/E11 -> 11.6896 | H11: =D11/F11 -> 1.4969469 | I11: =E11/F11 -> 0.12805801
A12: Frontier Airlines | B12: Indigo Partners | C12: 41548 | D12: 145 | E12: 15.425532 | F12: 185.89744 | G12: =D12/E12 -> 9.4 | H12: =D12/F12 -> 0.78 | I12: =E12/F12 -> 0.082978723
A13: US Airways Group | B13: AMR Corp. (American Airlines) | C13: 41318 | D13: 4905.082 | E13: 943.285 | F13: 7213.3559 | G13: =D13/E13 -> 5.2 | H13: =D13/F13 -> 0.68 | I13: =E13/F13 -> 0.13076923
A14: AirTran Holdings | B14: Southwest Airlines | C14: 40448 | D14: 3400 | E14: 459.45946 | F14: 2595.4198 | G14: =D14/E14 -> 7.4 | H14: =D14/F14 -> 1.31 | I14: =E14/F14 -> 0.17702703
A15: Continential Airlines | B15: UAL Corp. (United Airlines) | C15: 40301 | D15: 3170 | E15: 360.22727 | F15: 3170 | G15: =D15/E15 -> 8.8 | H15: =D15/F15 -> 1 | I15: =E15/F15 -> 0.11363636
A16: Northwest Airlines | B16: Delta Air Lines | C16: 39552 | D16: 3100 | E16: 516.66667 | F16: 3974.359 | G16: =D16/E16 -> 6 | H16: =D16/F16 -> 0.78 | I16: =E16/F16 -> 0.13
A17: Aeromexico | B17: Investor Group led by Banamex | C17: 39339 | D17: 1248.6 | E17: 126.12121 | F17: 1248.6 | G17: =D17/E17 -> 9.9 | H17: =D17/F17 -> 1 | I17: =E17/F17 -> 0.1010101
A18: Midwest Air Group | B18: Northwest Airlines / TPG Partners | C18: 39306 | D18: 450 | E18: 50.561798 | F18: 405.40541 | G18: =D18/E18 -> 8.9 | H18: =D18/F18 -> 1.11 | I18: =E18/F18 -> 0.1247191
A20: Average | D20: =AVERAGE(D11:D18) -> 2338.5485 | E20: =AVERAGE(E11:E18) -> 333.4528 | F20: =AVERAGE(F11:F18) -> 2540.3277 | G20: =AVERAGE(G11:G18) -> 8.4112 | H20: =AVERAGE(H11:H18) -> 1.0196184 | I20: =AVERAGE(I11:I18) -> 0.12352482
A21: Median | D21: =MEDIAN(D11:D18) -> 2694.853 | E21: =MEDIAN(E11:E18) -> 278.05138 | F21: =MEDIAN(F11:F18) -> 2062.5019 | G21: =MEDIAN(G11:G18) -> 8.85 | H21: =MEDIAN(H11:H18) -> 1 | I21: =MEDIAN(I11:I18) -> 0.12638855
A47: Source: Company press releases, Virgin America proxy statement from June 17, 2016

Sheet WACC
A1: Valuation Module | G1: This document subject to the Terms of Use
A2: WACC Analysis ($ in Millions) | G2: © 2013 Adventis CG Training LLC
A7: Inputs | E7: Cost of Debt Calculation
A9: Risk Free Rate | C9: 0.02883 | E9: Pre-Tax Cost of Debt | G9: =+C10 -> 0.0439
A10: Yield-to-Maturity of Debt | C10: 0.0439 | E10: Corporate Tax Rate | G10: =+C13 -> 0.265
A11: Equity Risk Premium | C11: 0.07141 | E11: After-Tax Cost of Debt | G11: =G9*(1-G10) -> 0.0322665
A12: Beta | C12: 1.2
A13: Corporate Tax Rate | C13: ='Income Statement'!H29 -> 0.265 | E13: Cost of Equity Calculation
A14: Common Shares | C14: ='Public Comps'!D25 -> 14.568284
A15: Share Price | C15: ='Public Comps'!C25 -> 63.24 | E15: Risk Free Rate | G15: =+C9 -> 0.02883
A16: Market Value of Debt | C16: ='Balance Sheet'!G24 -> 763.942 | E16: Equity Risk Premium | G16: =+C11 -> 0.07141
E17: Beta | G17: =+C12 -> 1.2
E18: Cost of Equity | G18: =+G15+G16*G17 -> 0.114522
A21: WACC Calculation
E23: Amount | F23: % Total | G23: Cost of Capital
A25: Market Value of Debt | E25: =+C16 -> 763.942 | F25: =+E25/$E$27 -> 0.45331341 | G25: =+G11 -> 0.0322665
A26: Market Value of Equity | E26: =+C15*C14 -> 921.29825 | F26: =+E26/$E$27 -> 0.54668659 | G26: =+G18 -> 0.114522
A27: Enterprise Value | E27: =SUM(E25:E26) -> 1685.2403 | F27: =+E27/$E$27 -> 1 | G27: =+G25*F25+G26*F26 -> 0.077234479

Sheet DCF
A1: Valuation Module | L1: This document subject to the Terms of Use
A2: Discounted Cash Flow Analysis ($ in Millions) | L2: © 2013 Adventis CG Training LLC
H6: Fiscal Year Ended December 31,
H7: 2019E | I7: 2020E | J7: 2021E | K7: 2022E | L7: 2023E | N7: Instructions:
A8: Discounted Cash Flow Analysis
A10: Years | H10: 1 | I10: 2 | J10: 3 | K10: 4 | L10: 5
A12: Revenue | H12: ='Income Statement'!H10 -> 1525.8389 | I12: ='Income Statement'!I10 -> 1617.3892 | J12: ='Income Statement'!J10 -> 1698.2587 | K12: ='Income Statement'!K10 -> 1757.6977 | L12: ='Income Statement'!L10 -> 1810.4287 | N12: Link to Income Statement
A13: Operating Expenses | H13: =+H12-H14 -> 1379.3583 | I13: =+I12-I14 -> 1463.7372 | J13: =+J12-J14 -> 1533.5276 | K13: =+K12-K14 -> 1585.4433 | L13: =+L12-L14 -> 1631.1962
A14: Operating Income | H14: ='Income Statement'!H14 -> 146.48053 | I14: ='Income Statement'!I14 -> 153.65197 | J14: ='Income Statement'!J14 -> 164.73109 | K14: ='Income Statement'!K14 -> 172.25438 | L14: ='Income Statement'!L14 -> 179.23244 | N14: Link to Income Statement
A15: Taxes @ | B15: ='Income Statement'!H29 -> 0.265 | H15: =H14*$B$15 -> 38.817341 | I15: =I14*$B$15 -> 40.717773 | J15: =J14*$B$15 -> 43.653739 | K15: =K14*$B$15 -> 45.64741 | L15: =L14*$B$15 -> 47.496596
A16: Tax-Effected EBIT | H16: =+H14-H15 -> 107.66319 | I16: =+I14-I15 -> 112.9342 | J16: =+J14-J15 -> 121.07735 | K16: =+K14-K15 -> 126.60697 | L16: =+L14-L15 -> 131.73584
A18: Plus: Depreciation | H18: ='Cash Flow Statement'!H11 -> 137.3255 | I18: ='Cash Flow Statement'!I11 -> 153.65197 | J18: ='Cash Flow Statement'!J11 -> 169.82587 | K18: ='Cash Flow Statement'!K11 -> 193.34675 | L18: ='Cash Flow Statement'!L11 -> 217.25144 | N18: Link to Cash Flow Statement
A19: Change in Working Capital | H19: ='Cash Flow Statement'!H12 -> 25.065093 | I19: ='Cash Flow Statement'!I12 -> 17.366346 | J19: ='Cash Flow Statement'!J12 -> 15.422903 | K19: ='Cash Flow Statement'!K12 -> 11.192469 | L19: ='Cash Flow Statement'!L12 -> 10.002624 | N19: Link to Cash Flow Statement
A20: Less: Capital Expenditures | H20: ='Cash Flow Statement'!H15 -> -167.84228 | I20: ='Cash Flow Statement'!I15 -> -258.78227 | J20: ='Cash Flow Statement'!J15 -> -169.82587 | K20: ='Cash Flow Statement'!K15 -> -202.13524 | L20: ='Cash Flow Statement'!L15 -> -217.25144 | N20: Link to Cash Flow Statement
A21: Unlevered Free Cash Flow | H21: =SUM(H18:H20,H16) -> 102.21151 | I21: =SUM(I18:I20,I16) -> 25.170249 | J21: =SUM(J18:J20,J16) -> 136.50025 | K21: =SUM(K18:K20,K16) -> 129.01095 | L21: =SUM(L18:L20,L16) -> 141.73847
A23: Present Value @ a Discount Rate of: | E23: =+WACC!$G$27 -> 0.077234479 | H23: =H21/(1+$E$23)^H10 -> 94.883249 | I23: =I21/(1+$E$23)^I10 -> 21.690373 | J23: =J21/(1+$E$23)^J10 -> 109.19499 | K23: =K21/(1+$E$23)^K10 -> 95.804428 | L23: =L21/(1+$E$23)^L10 -> 97.709434 | N23: Present Value = Future Value / (1 + Discount Rate)^Years
A24: Present Value of Projection Period | L24: =SUM(H23:L23) -> 419.28248
A27: Perpetuity Method | H27: EBITDA Exit Multiple Method
A29: Present Value of Projection Period | E29: =$L$24 -> 419.28248 | H29: Present Value of Projection Period | L29: =$L$24 -> 419.28248
A31: 2023 Free Cash Flow | E31: =L21 -> 141.73847 | H31: 2023 EBITDA | L31: =Debt!L42 -> 396.48387
A32: Perpetuity Growth Rate | E32: 0.02 | H32: EBITDA Multiple | L32: 5.5 | N32: Perpetuity Rate: 2023 FCF x [(1 + Perpetuity Growth Rate) / (Discount Rate - Perpetuity Growth Rate)]
A33: Terminal Value | E33: =E31*((1+E32)/(E23-E32)) -> 2525.9815 | H33: Terminal Value | L33: =L31*L32 -> 2180.6613 | N33: EBITDA Exit Multiple: 2023 EBITDA x EBITDA Multiple
A34: Years | E34: 5 | H34: Years | L34: 5
A35: Present Value of Terminal Value | E35: =E33/(1+$E$23)^E34 -> 1741.3214 | H35: Present Value of Terminal Value | L35: =L33/(1+$E$23)^L34 -> 1503.27 | N35: Present Value = Future Value / (1 + Discount Rate)^Years
A37: Total Enterprise Value | E37: =E29+E35 -> 2160.6039 | H37: Total Enterprise Value | L37: =SUM(L29,L35) -> 1922.5525 | N37: Present Value of Projection Period + Present Value of Terminal Value
A39: Implied EBITDA Multiple | E39: =+E33/L31 -> 6.3709564 | H39: Implied Perpetuity Growth Rate | L39: =(L33*E23-L21)/(L33+L21) -> 0.011489742 | N39: Implied EBITDA Multiple: Terminal Value / 2023 EBITDA
N40: Implied Perpetuity Growth Rate: (Terminal Value * Discount Rate - 2023 FCF) / (Terminal Value + 2023 FCF)

Sheet Valuation Output
A1: Valuation Module | N1: This document subject to the Terms of Use
A2: Valuation Summary ($ in Millions) | N2: © 2013 Adventis CG Training LLC
D6: Target | F6: Enterprise | H6: Net | J6: Equity | L6: Shares | N6: Stock
D7: Metric | E7: Multiple | F7: Value | G7: - | H7: Debt | I7: = | J7: Value | K7: / | L7: Outstanding | M7: = | N7: Price | P7: Instructions:
A8: Comparable Companies Analysis
A10: 2019 Revenue | D10: ='Income Statement'!$H$10 -> 1525.8389 | E10: 1 | F10: =D10*E10 -> 1525.8389 | H10: =+'Balance Sheet'!$G$37 -> 602.09498 | J10: =F10-H10 -> 923.7439 | L10: =+'Public Comps'!$D$25 -> 14.568284 | N10: =J10/L10 -> 63.407875 | P10: Revenue x Multiple = Enterprise Value
A11: 2019 EBITDA | D11: =Debt!$H$42 -> 283.80603 | E11: 5 | F11: =D11*E11 -> 1419.0302 | H11: =+'Balance Sheet'!$G$37 -> 602.09498 | J11: =F11-H11 -> 816.93518 | L11: =+'Public Comps'!$D$25 -> 14.568284 | N11: =J11/L11 -> 56.076282 | P11: EBITDA x Multiple = Enterprise Value
A12: 2019 Net Earnings | D12: ='Income Statement'!H25 -> 94.717136 | E12: 9.5 | F12: =H12+J12 -> 1501.9078 | H12: =+'Balance Sheet'!$G$37 -> 602.09498 | J12: =D12*E12 -> 899.81279 | L12: =+'Public Comps'!$D$25 -> 14.568284 | N12: =J12/L12 -> 61.765189 | P12: Net Earnings x Multiple = Equity Value
A14: Acquisition Comparables Analysis
A16: 2018 Revenue | D16: ='Income Statement'!$G$10 -> 1419.385 | E16: 1.3 | F16: =D16*E16 -> 1845.2005 | H16: =+'Balance Sheet'!$G$37 -> 602.09498 | J16: =F16-H16 -> 1243.1055 | L16: =+'Public Comps'!$D$25 -> 14.568284 | N16: =J16/L16 -> 85.32958 | P16: Revenue x Multiple = Enterprise Value
A17: 2018 EBITDA | D17: =+'Income Statement'!G14-'PP&E'!G12 -> 250.673 | E17: 8 | F17: =D17*E17 -> 2005.384 | H17: =+'Balance Sheet'!$G$37 -> 602.09498 | J17: =F17-H17 -> 1403.289 | L17: =+'Public Comps'!$D$25 -> 14.568284 | N17: =J17/L17 -> 96.324939 | P17: EBITDA x Multiple = Enterprise Value
A19: Discounted Cash Flow Analysis
A21: Perpetuity Method | F21: =DCF!$E$37 -> 2160.6039 | H21: =+'Balance Sheet'!$G$37 -> 602.09498 | J21: =F21-H21 -> 1558.5089 | L21: =+'Public Comps'!$D$25 -> 14.568284 | N21: =J21/L21 -> 106.97958 | P21: Link in Enterprise Value to the DCF Tab
A22: EBITDA Exit Multiple Method | F22: =DCF!$L$37 -> 1922.5525 | H22: =+'Balance Sheet'!$G$37 -> 602.09498 | J22: =F22-H22 -> 1320.4575 | L22: =+'Public Comps'!$D$25 -> 14.568284 | N22: =J22/L22 -> 90.639196
A24: Current Valuation | F24: =H24+J24 -> 1523.3932 | H24: =+'Balance Sheet'!$G$37 -> 602.09498 | J24: =N24*L24 -> 921.29825 | L24: =+'Public Comps'!$D$25 -> 14.568284 | N24: =+'Public Comps'!C25 -> 63.24 | P24: Insert current stock price and work backwards

Sheet LBO
A1: Leveraged Buyout Module | T1: This document subject to the Terms of Use
A2: Leverage Buyout Analysis ($ in Millions) | T2: © 2013 Adventis CG Training LLC
A6: Pro Forma Financial Statements | L6: Transaction Value
E7: 2018A | F7: 2019E | G7: 2020E | H7: 2021E | I7: 2022E | J7: 2023E | L7: Current Share Price | T7: =+'Public Comps'!C25 -> 63.24
A8: Revenue | E8: ='Income Statement'!G10 -> 1419.385 | F8: ='Income Statement'!H10 -> 1525.8389 | G8: ='Income Statement'!I10 -> 1617.3892 | H8: ='Income Statement'!J10 -> 1698.2587 | I8: ='Income Statement'!K10 -> 1757.6977 | J8: ='Income Statement'!L10 -> 1810.4287 | L8: Premium | T8: 0.4
A9: Total Expenses | E9: =E8-E10 -> 1290.425 | F9: =F8-F10 -> 1379.3583 | G9: =G8-G10 -> 1463.7372 | H9: =H8-H10 -> 1533.5276 | I9: =I8-I10 -> 1585.4433 | J9: =J8-J10 -> 1631.1962 | L9: Offer Price | T9: =T7*(1+T8) -> 88.536
A10: EBIT | E10: ='Income Statement'!G14 -> 128.96 | F10: ='Income Statement'!H14 -> 146.48053 | G10: ='Income Statement'!I14 -> 153.65197 | H10: ='Income Statement'!J14 -> 164.73109 | I10: ='Income Statement'!K14 -> 172.25438 | J10: ='Income Statement'!L14 -> 179.23244 | L10: Shares Outstanding | T10: =+'Public Comps'!$D$25 -> 14.568284
A11: Interest Expense | E11: ='Income Statement'!G17 -> 24.004929 | F11: =F53 -> 89.328402 | G11: =G53 -> 87.578947 | H11: =H53 -> 84.890731 | I11: =I53 -> 81.306831 | J11: =J53 -> 77.455351 | L11: Purchase Price | T11: =T9*T10 -> 1289.8176
A12: Earnings Before Taxes | E12: =E10-E11 -> 104.95507 | F12: =F10-F11 -> 57.15213 | G12: =G10-G11 -> 66.073028 | H12: =H10-H11 -> 79.84036 | I12: =I10-I11 -> 90.947546 | J12: =J10-J11 -> 101.77709 | L12: Plus: Debt | T12: ='Balance Sheet'!G24 -> 763.942
A13: Taxes @ | C13: ='Income Statement'!H29 -> 0.265 | E13: =E12*$C$13 -> 27.813094 | F13: =F12*$C$13 -> 15.145315 | G13: =G12*$C$13 -> 17.509352 | H13: =H12*$C$13 -> 21.157695 | I13: =I12*$C$13 -> 24.1011 | J13: =J12*$C$13 -> 26.970928 | L13: Less: Cash | T13: =-'Balance Sheet'!G10 -> -161.84702
A14: Net Income | E14: =E12-E13 -> 77.141977 | F14: =F12-F13 -> 42.006816 | G14: =G12-G13 -> 48.563676 | H14: =H12-H13 -> 58.682665 | I14: =I12-I13 -> 66.846446 | J14: =J12-J13 -> 74.806158 | L14: Transaction Value | T14: =SUM(T11:T13) -> 1891.9125
A16: Plus: Depreciation & Amortization | E16: =-'PP&E'!G12 -> 121.713 | F16: =-'PP&E'!H12 -> 137.3255 | G16: =-'PP&E'!I12 -> 153.65197 | H16: =-'PP&E'!J12 -> 169.82587 | I16: =-'PP&E'!K12 -> 193.34675 | J16: =-'PP&E'!L12 -> 217.25144 | L16: 2018 EBITDA | T16: =E16+E10 -> 250.673
