Workbook

Sheet Terms of Use
A2: Terms of Use
A4: This Document is subject to the Adventis Terms of Use (“TOU”) appearing on its web site. The TOU include, but are not limited to, restrictions on use of Documents, a disclaimer of all warranties and conditions of merchantability, and limitations of liability.
A7: Product protected by copyright
A8: © 2013 Adventis CG Training LLC

Sheet Income Statement
A1: Adventis Air Company Financial Model | L1: This document subject to the Terms of Use
A2: Income Statement ($ in Millions) | L2: © 2013 Adventis CG Training LLC
E6: Fiscal Year Ended December 31,
E7: 2016A | F7: 2017A | G7: 2018A | H7: 2019E | I7: 2020E | J7: 2021E | K7: 2022E | L7: 2023E | N7: Instructions:
A8: Income Statement
A10: Revenue | E10: 1253.004 | F10: 1341.587 | G10: 1419.385 | H10: =G10*(1+H11) -> 1525.8389 | I10: =H10*(1+I11) -> 1617.3892 | J10: =I10*(1+J11) -> 1698.2587 | K10: =J10*(1+K11) -> 1757.6977 | L10: =K10*(1+L11) -> 1810.4287 | N10: Previous Year's Revenue x (1 + Growth Rate)
A11: % Growth | F11: =F10/E10-1 -> 0.070696502 | G11: =G10/F10-1 -> 0.05798953 | H11: 0.075 | I11: 0.06 | J11: 0.05 | K11: 0.035 | L11: 0.03 | N11: Revenue / Previous Year's Revenue - 1
A13: Operating Expenses | E13: 1128.644 | F13: 1218.02 | G13: 1290.425 | H13: =H10-H14 -> 1379.3583 | I13: =I10-I14 -> 1463.7372 | J13: =J10-J14 -> 1533.5276 | K13: =K10-K14 -> 1585.4433 | L13: =L10-L14 -> 1631.1962 | N13: Revenue - Operating Income
A14: Operating Income | E14: =E10-E13 -> 124.36 | F14: =F10-F13 -> 123.567 | G14: =G10-G13 -> 128.96 | H14: =H15*H10 -> 146.48053 | I14: =I15*I10 -> 153.65197 | J14: =J15*J10 -> 164.73109 | K14: =K15*K10 -> 172.25438 | L14: =L15*L10 -> 179.23244 | N14: % Operating Margin x Revenue
A15: % Operating Margin | E15: =E14/E10 -> 0.099249484 | F15: =F14/F10 -> 0.092105096 | G15: =G14/G10 -> 0.090856251 | H15: 0.096 | I15: 0.095 | J15: 0.097 | K15: 0.098 | L15: 0.099
A17: Interest Expense | E17: 19.674075 | F17: 22.466662 | G17: 24.004929 | N17: Step 10: Link into the Interest Expense Schedule
A18: Interest Income | E18: -9.030486 | F18: -8.906568 | G18: -6.986032 | N18: Step 10: Link into the Interest Income Schedule
A19: Other Expense (Income) | E19: -0.075 | F19: -1.226 | G19: -1.559 | H19: -4 | I19: -6 | J19: -7 | K19: -9 | L19: -11
A20: Total Other Expenses | E20: =SUM(E17:E19) -> 10.568589 | F20: =SUM(F17:F19) -> 12.334094 | G20: =SUM(G17:G19) -> 15.459897 | H20: =SUM(H17:H19) -> -4 | I20: =SUM(I17:I19) -> -6 | J20: =SUM(J17:J19) -> -7 | K20: =SUM(K17:K19) -> -9 | L20: =SUM(L17:L19) -> -11
A22: Earnings Before Taxes | E22: =E14-E20 -> 113.79141 | F22: =F14-F20 -> 111.23291 | G22: =G14-G20 -> 113.5001 | H22: =H14-H20 -> 150.48053 | I22: =I14-I20 -> 159.65197 | J22: =J14-J20 -> 171.73109 | K22: =K14-K20 -> 181.25438 | L22: =L14-L20 -> 190.23244 | N22: Operating Income - Total Other Expenses
A24: Corporate Taxes | E24: 41.480227 | F24: 40.377545 | G24: 29.850527 | H24: =H22*H29 -> 39.877341 | I24: =I22*I29 -> 42.307773 | J24: =J22*J29 -> 45.508739 | K24: =K22*K29 -> 48.03241 | L24: =L22*L29 -> 50.411596 | N24: Earnings Before Taxes x Corporate Tax Rate
A25: Net Earnings | E25: =E22-E24 -> 72.311185 | F25: =F22-F24 -> 70.855361 | G25: =G22-G24 -> 83.649576 | H25: =H22-H24 -> 110.60319 | I25: =I22-I24 -> 117.3442 | J25: =J22-J24 -> 126.22235 | K25: =K22-K24 -> 133.22197 | L25: =L22-L24 -> 139.82084 | N25: Earnings Before Taxes - Corporate Taxes
A26: % Net Margin | E26: =E25/E10 -> 0.057710259 | F26: =F25/F10 -> 0.052814586 | G26: =G25/G10 -> 0.058933676 | H26: =H25/H10 -> 0.072486809 | I26: =I25/I10 -> 0.072551616 | J26: =J25/J10 -> 0.074324574 | K26: =K25/K10 -> 0.075793446 | L26: =L25/L10 -> 0.077230793 | N26: Net Earnings / Revenue
A28: Metrics & Drivers
A29: Corporate Tax Rate | E29: =E24/E22 -> 0.36452862 | F29: =F24/F22 -> 0.363 | G29: =G24/G22 -> 0.263 | H29: 0.265 | I29: 0.265 | J29: 0.265 | K29: 0.265 | L29: 0.265 | N29: Corporate Taxes / Earnings before Taxes

Sheet Balance Sheet
A1: Adventis Air Company Financial Model | L1: This document subject to the Terms of Use
A2: Balance Sheet ($ in Millions) | L2: © 2013 Adventis CG Training LLC
E6: Fiscal Year Ended December 31,
E7: 2016A | F7: 2017A | G7: 2018A | H7: 2019E | I7: 2020E | J7: 2021E | K7: 2022E | L7: 2023E | N7: Instructions:
A8: Balance Sheet
A10: Cash and Cash Equivalents | E10: 274.32188 | F10: 277.49725 | G10: 161.84702 | H10: 161.84702 | I10: 161.84702 | J10: 161.84702 | K10: 161.84702 | L10: 161.84702 | N10: Step 6: Link into the Cash Flow Statement
A11: Accounts Receivable | E11: 21.815 | F11: 23.667 | G11: 24.563 | H11: 24.563 | I11: 24.563 | J11: 24.563 | K11: 24.563 | L11: 24.563 | N11: Step 7: Link into the Working Capital Schedule
A12: Other Current Assets | E12: 37.123 | F12: 38.615 | G12: 46.482 | H12: 46.482 | I12: 46.482 | J12: 46.482 | K12: 46.482 | L12: 46.482 | N12: Step 7: Link into the Working Capital Schedule
A13: Total Current Assets | E13: =SUM(E10:E12) -> 333.25988 | F13: =SUM(F10:F12) -> 339.77925 | G13: =SUM(G10:G12) -> 232.89202 | H13: =SUM(H10:H12) -> 232.89202 | I13: =SUM(I10:I12) -> 232.89202 | J13: =SUM(J10:J12) -> 232.89202 | K13: =SUM(K10:K12) -> 232.89202 | L13: =SUM(L10:L12) -> 232.89202
A15: Net Property, Plant & Equipment | E15: 857.765 | F15: 947.292 | G15: 1214.018 | H15: 1214.018 | I15: 1214.018 | J15: 1214.018 | K15: 1214.018 | L15: 1214.018 | N15: Step 6: Link into the PP&E Schedule
A16: Other Long-Term Assets | E16: 66.622 | F16: 73.459 | G16: 49.516 | H16: 49.516 | I16: 49.516 | J16: 49.516 | K16: 49.516 | L16: 49.516
A17: Total Assets | E17: =SUM(E15:E16,E13) -> 1257.6469 | F17: =SUM(F15:F16,F13) -> 1360.5302 | G17: =SUM(G15:G16,G13) -> 1496.426 | H17: =SUM(H15:H16,H13) -> 1496.426 | I17: =SUM(I15:I16,I13) -> 1496.426 | J17: =SUM(J15:J16,J13) -> 1496.426 | K17: =SUM(K15:K16,K13) -> 1496.426 | L17: =SUM(L15:L16,L13) -> 1496.426
A19: Accounts Payable | E19: 6.901 | F19: 16.01 | G19: 20.108 | H19: 20.108 | I19: 20.108 | J19: 20.108 | K19: 20.108 | L19: 20.108 | N19: Step 7: Link into the Working Capital Schedule
A20: Accrued Liabilities | E20: 115.131 | F20: 96.661 | G20: 105.127 | H20: 105.127 | I20: 105.127 | J20: 105.127 | K20: 105.127 | L20: 105.127 | N20: Step 7: Link into the Working Capital Schedule
A21: Other Current Liabilities | E21: 197.136 | F21: 194.001 | G21: 210.184 | H21: 210.184 | I21: 210.184 | J21: 210.184 | K21: 210.184 | L21: 210.184 | N21: Step 7: Link into the Working Capital Schedule
A22: Total Current Liabilities | E22: =SUM(E19:E21) -> 319.168 | F22: =SUM(F19:F21) -> 306.672 | G22: =SUM(G19:G21) -> 335.419 | H22: =SUM(H19:H21) -> 335.419 | I22: =SUM(I19:I21) -> 335.419 | J22: =SUM(J19:J21) -> 335.419 | K22: =SUM(K19:K21) -> 335.419 | L22: =SUM(L19:L21) -> 335.419
A24: Total Debt | E24: 588.18 | F24: 695.26 | G24: 763.942 | H24: 763.942 | I24: 763.942 | J24: 763.942 | K24: 763.942 | L24: 763.942 | N24: Step 9: Link into the Debt Schedule
A25: Other Long-Term Liabilities | E25: 49.255 | F25: 78.607 | G25: 122.14 | H25: 122.14 | I25: 122.14 | J25: 122.14 | K25: 122.14 | L25: 122.14
A26: Total Liabilities | E26: =SUM(E24:E25,E22) -> 956.603 | F26: =SUM(F24:F25,F22) -> 1080.539 | G26: =SUM(G24:G25,G22) -> 1221.501 | H26: =SUM(H24:H25,H22) -> 1221.501 | I26: =SUM(I24:I25,I22) -> 1221.501 | J26: =SUM(J24:J25,J22) -> 1221.501 | K26: =SUM(K24:K25,K22) -> 1221.501 | L26: =SUM(L24:L25,L22) -> 1221.501
A28: Shareholders' Equity | E28: 301.04388 | F28: 279.99125 | G28: 274.92502 | H28: 274.92502 | I28: 274.92502 | J28: 274.92502 | K28: 274.92502 | L28: 274.92502 | N28: Step 8: Link into the Equity Schedule
A29: Total Liabilities and Equity | E29: =SUM(E28,E26) -> 1257.6469 | F29: =SUM(F28,F26) -> 1360.5302 | G29: =SUM(G28,G26) -> 1496.426 | H29: =SUM(H28,H26) -> 1496.426 | I29: =SUM(I28,I26) -> 1496.426 | J29: =SUM(J28,J26) -> 1496.426 | K29: =SUM(K28,K26) -> 1496.426 | L29: =SUM(L28,L26) -> 1496.426
A31: check | E31: =E17-E29 -> 0 | F31: =F17-F29 -> 0 | G31: =G17-G29 -> 0 | H31: =H17-H29 -> 0 | I31: =I17-I29 -> 0 | J31: =J17-J29 -> 0 | K31: =K17-K29 -> 0 | L31: =L17-L29 -> 0 | N31: Total Assets - Total Liabilities & Equity
A33: Metrics & Drivers
A34: Net Earnings | E34: ='Income Statement'!E25 -> 72.311185 | F34: ='Income Statement'!F25 -> 70.855361 | G34: ='Income Statement'!G25 -> 83.649576 | H34: ='Income Statement'!H25 -> 110.60319 | I34: ='Income Statement'!I25 -> 117.3442 | J34: ='Income Statement'!J25 -> 126.22235 | K34: ='Income Statement'!K25 -> 133.22197 | L34: ='Income Statement'!L25 -> 139.82084 | N34: Link to the Income Statement
A35: Cash Ratio | E35: =E10/E22 -> 0.85949057 | F35: =F10/F22 -> 0.90486659 | G35: =G10/G22 -> 0.48252193 | H35: =H10/H22 -> 0.48252193 | I35: =I10/I22 -> 0.48252193 | J35: =J10/J22 -> 0.48252193 | K35: =K10/K22 -> 0.48252193 | L35: =L10/L22 -> 0.48252193 | N35: Cash and Cash Equivalents / Total Current Liabilities
A36: Return on Equity | E36: =E34/E28 -> 0.24020147 | F36: =F34/F28 -> 0.25306277 | G36: =G34/G28 -> 0.30426323 | H36: =H34/H28 -> 0.40230311 | I36: =I34/I28 -> 0.42682256 | J36: =J34/J28 -> 0.45911555 | K36: =K34/K28 -> 0.48457563 | L36: =L34/L28 -> 0.50857808 | N36: Net Earnings / Shareholders' Equity
A37: Net Debt | E37: =E24-E10 -> 313.85812 | F37: =F24-F10 -> 417.76275 | G37: =G24-G10 -> 602.09498 | H37: =H24-H10 -> 602.09498 | I37: =I24-I10 -> 602.09498 | J37: =J24-J10 -> 602.09498 | K37: =K24-K10 -> 602.09498 | L37: =L24-L10 -> 602.09498 | N37: Total Debt - Cash and Cash Equivalents
A42: Note: Current Maturities of Long-Term Debt has been combined with Total Debt and designated as a long-term liability for training purposes. Cash and Cash
A43: Equivalents includes Restricted Cash and Short-Term Investments.

Sheet Cash Flow Statement
A1: Adventis Air Company Financial Model | L1: This document subject to the Terms of Use
A2: Cash Flow Statement ($ in Millions) | L2: © 2013 Adventis CG Training LLC
E6: Fiscal Year Ended December 31,
E7: 2016A | F7: 2017A | G7: 2018A | H7: 2019E | I7: 2020E | J7: 2021E | K7: 2022E | L7: 2023E | N7: Instructions:
A8: Cash Flow Statement
A10: Net Earnings | E10: 274.32188 | F10: 277.49725 | G10: 161.84702 | N10: Step 8: Link into the Income Statement
A11: Depreciation | E11: 21.815 | F11: 23.667 | G11: 24.563 | N11: Step 6: Link into the PP&E Schedule
A12: Change in Working Capital | E12: 37.123 | F12: 38.615 | G12: 46.482 | N12: Step 7: Link into the Working Capital Schedule
A13: Cash From Operating Activities | E13: =SUM(E10:E12) -> 333.25988 | F13: =SUM(F10:F12) -> 339.77925 | G13: =SUM(G10:G12) -> 232.89202
A15: Capital Expenditures | E15: 857.765 | F15: 947.292 | G15: 1214.018 | N15: Step 6: Link into the PP&E Schedule
A16: Cash From Investing Activities | E16: 66.622 | F16: 73.459 | G16: 49.516
E17: =SUM(E15:E16,E13) -> 1257.6469 | F17: =SUM(F15:F16,F13) -> 1360.5302 | G17: =SUM(G15:G16,G13) -> 1496.426
A18: Dividends | N18: Step 8: Link into the Equity Schedule
A19: Share Repurchases | E19: 6.901 | F19: 16.01 | G19: 20.108 | N19: Step 8: Link into the Equity Schedule
A20: Change in Revolver | E20: 115.131 | F20: 96.661 | G20: 105.127 | N20: Step 9: Link into the Debt Schedule
A21: Change in Long-Term Debt | E21: 197.136 | F21: 194.001 | G21: 210.184 | N21: Step 9: Link into the Debt Schedule
A22: Cash From Financing Activities | E22: =SUM(E19:E21) -> 319.168 | F22: =SUM(F19:F21) -> 306.672 | G22: =SUM(G19:G21) -> 335.419
A24: Change in Cash | E24: 588.18 | F24: 695.26 | G24: 763.942
E25: 49.255 | F25: 78.607 | G25: 122.14
A26: Beginning Cash | E26: =SUM(E24:E25,E22) -> 956.603 | F26: =SUM(F24:F25,F22) -> 1080.539 | G26: =SUM(G24:G25,G22) -> 1221.501 | N26: Step 5: Link to the ending balance of the previous year
A27: Ending Cash | N27: Step 5: Link 2018A into the Balance Sheet
E28: 301.04388 | F28: 279.99125 | G28: 274.92502
A29: Metrics & Drivers | E29: =SUM(E28,E26) -> 1257.6469 | F29: =SUM(F28,F26) -> 1360.5302 | G29: =SUM(G28,G26) -> 1496.426
A30: Free Cash Flow (Levered) | N30: Cash Flow from Operating Activities - Capital Expenditures
A31: Operating Income | E31: =E17-E29 -> 0 | F31: =F17-F29 -> 0 | G31: =G17-G29 -> 0 | N31: Link to the Income Statement
A32: EBITDA | N32: Operating Income + Depreciation

Sheet PP&E
A1: Adventis Air Company Financial Model | L1: This document subject to the Terms of Use
A2: PP&E Schedule ($ in Millions) | L2: © 2013 Adventis CG Training LLC
E6: Fiscal Year Ended December 31,
E7: 2016A | F7: 2017A | G7: 2018A | H7: 2019E | I7: 2020E | J7: 2021E | K7: 2022E | L7: 2023E | N7: Instructions:
A8: PP&E Schedule
A10: Beginning Balance of PP&E | N10: Link to the ending balance of the previous year
A11: Plus: Capital Expenditures | N11: Revenue x Capital Expenditures as a % Revenue
A12: Less: Depreciation | N12: Revenue x Depreciation as a % Revenue
A13: Ending Balance of PP&E | N13: Link 2018A into the Balance Sheet
A15: Metrics & Drivers
A16: Revenue | N16: Link into the Income Statement
A17: Capital Expenditures as a % Revenue | N17: Capital Expenditures / Revenue
A18: Depreciation as a % Revenue | N18: Depreciation / Revenue

Sheet Working Capital
A1: Adventis Air Company Financial Model | L1: This document subject to the Terms of Use
A2: Working Capital Schedule ($ in Millions) | L2: © 2013 Adventis CG Training LLC
E6: Fiscal Year Ended December 31,
E7: 2016A | F7: 2017A | G7: 2018A | H7: 2019E | I7: 2020E | J7: 2021E | K7: 2022E | L7: 2023E | N7: Instructions:
A8: Working Capital Schedule
A10: Accounts Receivable | N10: Days Receivable x Revenue / Days
A11: Other Current Assets | N11: Revenue x Other Current Assets as a % of Revenue
A12: Non-Cash Current Assets
A14: Accounts Payable | N14: Revenue x Accounts Payable as a % of Revenue
A15: Accrued Liabilities | N15: Revenue x Accrued Liabilities as a % of Revenue
A16: Other Current Liabilities | N16: Revenue x Other Current Liabilities as a % of Revenue
A17: Non-Debt Current Liabilities
A19: Working Capital | N19: Non-Cash Current Assets - Non-Debt Current Liabilities
A20: Change in Working Capital | N20: Current Year's Working Capital - Previous Year's Working Capital
A22: Metrics & Drivers
A23: Revenue | N23: Link into the Income Statement
A24: Days Receivable | N24: Accounts Receivable / Revenue x Days
A25: Other Current Assets as a % Revenue | N25: Other Current Assets / Revenue
A26: Accounts Payable as a % of Revenue | N26: Accounts Payable / Revenue
A27: Accrued Liabilities as a % of Revenue | N27: Accrued Liabilities / Revenue
A28: Other Current Liabilities as a % Revenue | N28: Other Current Liabilities / Revenue
A29: Days

Sheet Equity
A1: Adventis Air Company Financial Model | L1: This document subject to the Terms of Use
A2: Equity Schedule ($ in Millions) | L2: © 2013 Adventis CG Training LLC
E6: Fiscal Year Ended December 31,
E7: 2016A | F7: 2017A | G7: 2018A | H7: 2019E | I7: 2020E | J7: 2021E | K7: 2022E | L7: 2023E | N7: Instructions:
A8: Equity Schedule
A10: Beginning Balance of Equity | N10: Link to the ending balance of the previous year
A11: Plus: Net Earnings | N11: Link into the Income Statement
A12: Less: Dividends | N12: Link into the Dividend Schedule
A13: Less: Share Repurchases | N13: Link into the Share Repurchase Schedule
A14: Ending Balance of Equity | N14: Link 2018A into the Balance Sheet
A16: Common Stock Schedule
A18: Beginning Balance of Shares Outstanding
A19: No. of Shares Repurchased | N19: Link to row 30
A20: No. of Shares Issued
A21: Ending Balance of Shares Outstanding
A23: Metrics & Drivers
A24: Average Common Shares Outstanding | N24: =Average (Beginning Balance of Shares Outstanding, Ending Balance of Shares Outstanding)
A25: Net Earnings | N25: Link into the Income Statement
A26: Basic Earnings per Share | N26: Net Earnings / Average Common Shares Outstanding
A28: Share Repurchases Schedule
A30: No. of Shares Repurchased | N30: Link to row 19; Share Repurchases ($) / Average Price Paid per Share
A31: x Average Price Paid per Share | N31: Share Repurchases ($) / No. of Shares Repurchased; P/E Multiple * Basic Earnings per Share
A32: Share Repurchases ($)
A34: Metrics & Drivers
A35: P/E Multiple | N35: Average Price Paid per Share / Basic Earnings per Share
A37: Dividends Schedule
A39: Average Common Shares Outstanding | N39: Link to row 24
A40: x Dividends per Share | N40: Dividends ($) / Average Common Shares Outstanding
A41: Dividends ($) | N41: Average Common Shares Outstanding x Dividends per Share
A43: Metrics & Drivers
A44: Dividend Yield | N44: Dividend per Share / Average Price Paid per Share

Sheet Debt
A1: Adventis Air Company Financial Model | L1: This document subject to the Terms of Use
A2: Debt Schedule ($ in Millions) | L2: © 2013 Adventis CG Training LLC
E6: Fiscal Year Ended December 31,
E7: 2016A | F7: 2017A | G7: 2018A | H7: 2019E | I7: 2020E | J7: 2021E | K7: 2022E | L7: 2023E | N7: Instructions:
A8: Beginning Debt
A10: Revolver Beginning Balance | N10: Link to the Ending Balance of the previous year
A11: Long-Term Debt Beginning Balance | N11: Link to the Ending Balance of the previous year
A12: Total Beginning Debt Balance
A14: Debt Pay Down and Issuance
A16: Beginning Cash Balance | N16: Link into the Balance Sheet
A17: Cash From Operating Activities | N17: Link into the Cash Flow Statement
A18: Cash From Investing Activities | N18: Link into the Cash Flow Statement
A19: Dividends | N19: Link into the Cash Flow Statement
A20: Share Repurchases | N20: Link into the Cash Flow Statement
A21: Long-Term Debt Paydown (Scheduled)
A22: Less: Minimum Cash Balance
A23: Total Cash Available (Required)
A25: Revolver Issued | N25: =IF(H23<0,-H23,0)
A26: Long-Term Debt Issued
A27: Total Cash Available
A29: Revolver Paydown | N29: =-IF(H27>0,MIN(H10,H27),0)
A30: Long-Term Debt Paydown | N30: Link into row 21
A31: Total Debt Paydown
A33: Ending Debt
A35: Revolver Ending Balance | N35: Beginning Revolver Balance + Revolver Issued + Revolver Paydown
A36: Long-Term Debt Ending Balance | N36: Beginning Long-Term Debt Balance + Long-Term Debt Issued + Long-Term Debt Paydown
A37: Total Ending Debt Balance
A39: Metrics & Drivers
A40: Change in Revolver | N40: Revolver Issued + Revolver Paydown
A41: Change in Long-Term Debt | N41: Long-Term Debt Issued + Long-Term Debt Paydown
A42: EBITDA | N42: Link to the Cash Flow Statement
A43: Shareholders' Equity | N43: Link to the Balance Sheet
A44: Debt / EBITDA | N44: Total Ending Debt Balance / EBITDA
A45: Debt-to-Equity Ratio | N45: Total Ending Debt Balance / Shareholders' Equity

Sheet Interest
A1: Adventis Air Company Financial Model | L1: This document subject to the Terms of Use
A2: Interest Schedule ($ in Millions) | L2: © 2013 Adventis CG Training LLC
E6: Fiscal Year Ended December 31,
E7: 2016A | F7: 2017A | G7: 2018A | H7: 2019E | I7: 2020E | J7: 2021E | K7: 2022E | L7: 2023E | N7: Instructions:
A8: Interest Expense Schedule
A10: Revolver Average Balance | N10: =Average(Revolver Beginning Balance,Revolver Ending Balance)
A11: Long-Term Debt Average Balance | N11: =Average(Long-Term Debt Beginning Balance,Long-Term Debt Ending Balance)
A12: Average Debt Balance
A14: Revolver Interest Rate
A15: Long-Term Debt Interest Rate
A16: Average Interest Rate | N16: Total Interest Expense / Average Debt Balance
A18: Revolver Interest Expense | N18: Revolver Average Balance x Revolver Interest Rate
A19: Long-Term Debt Interest Expense | N19: Long-Term Debt Average Balance x Long-Term Debt Interest Rate
A20: Total Interest Expense
A22: Metrics & Drivers
A23: Revolver Beginning Balance | N23: Link into the Debt Schedule
A24: Long-Term Debt Beginning Balance | N24: Link into the Debt Schedule
A25: Revolver Ending Balance | N25: Link into the Debt Schedule
A26: Long-Term Debt Ending Balance | N26: Link into the Debt Schedule
A28: Interest Income Schedule
A30: Average Cash Balance | N30: =Average(Cash Beginning Balance,Cash Ending Balance)
A31: Interest Rate on Cash
A32: Total Interest Income
A34: Metrics & Drivers
A35: Cash Beginning Balance | N35: Link into the Cash Flow Statement
A36: Cash Ending Balance | N36: Link into the Cash Flow Statement

Sheet Public Comps
A1: Valuation Module | P1: This document subject to the Terms of Use
A2: Public Comparables Analysis ($ in Millions) | P2: © 2013 Adventis CG Training LLC
K7: Enterprise Value /
C8: Share | D8: Shares | E8: Market | F8: Net | G8: Enterprise | H8: Sales CAGR | I8: EBITDA Margin | K8: EBITDA | M8: Sales | O8: Price / Earnings | S8: EBITDA | U8: Sales | X8: EPS | Z8: Total
C9: Price | D9: Outstanding | E9: Cap | F9: Debt | G9: Value | H9: 18A-20E | I9: 2019E | J9: 2020E | K9: 2019E | L9: 2020E | M9: 2019E | N9: 2020E | O9: 2019E | P9: 2020E | R9: Ticker | S9: 2019E | T9: 2020E | U9: 2018A | V9: 2019E | W9: 2020E | X9: 2019E | Y9: 2020E | Z9: Debt | AA9: Cash
A11: Delta Air Lines | C11: 57.71 | D11: 676.55 | R11: DAL | S11: 8693.4167 | T11: 8984.5833 | U11: 44438 | V11: 46445.333 | W11: 48564.176 | X11: 6.464 | Y11: 6.858 | Z11: 16131 | AA11: 1768
A12: Southwest Airlines | C12: 51.94 | D12: 552.69 | R12: LUV | S12: 4691.5 | T12: 5015 | U12: 21965 | V12: 23246 | W12: 24886.235 | X12: 4.729 | Y12: 5.226 | Z12: 2660 | AA12: 3689
A13: American Airlines | C13: 33.88 | D13: 449.06 | R13: AAL | S13: 6554.4615 | T13: 6592.8462 | U13: 44541 | V13: 46531.647 | W13: 48512.412 | X13: 5.6233333 | Y13: 5.7455556 | Z13: 33335 | AA13: 4760
A14: United Continential Holdings | C14: 84.58 | D14: 266.73 | R14: UAL | S14: 6779.5833 | T14: 7037.75 | U14: 41303 | V14: 43410.941 | W14: 45942.353 | X14: 11.066 | Y14: 11.974 | Z14: 14728 | AA14: 3950
A15: Alaska Air Group | C15: 58.33 | D15: 123.61 | R15: ALK | S15: 1503.1429 | T15: 1616.8571 | U15: 8264 | V15: 8683.7 | W15: 9218.2 | X15: 5.984 | Y15: 6.57 | Z15: 2110 | AA15: 1236
A16: JetBlue Airways | C16: 16.34 | D16: 300.95 | R16: JBLU | S16: 1377.2 | T16: 1555.6 | U16: 7658 | V16: 8190.6667 | W16: 8873.8571 | X16: 1.82 | Y16: 2.13625 | Z16: 2099 | AA16: 887
A17: Spirit Airlines | C17: 54.7 | D17: 68.33 | R17: SAVE | S17: 863 | T17: 948.54545 | U17: 3323.034 | V17: 3921.6 | W17: 4500.7857 | X17: 6.47375 | Y17: 6.79375 | Z17: 2186.776 | AA17: 1107.522
A18: Allegiant Travel | C18: 133.87 | D18: 16.09 | R18: ALGT | S18: 501.75 | T18: 539.625 | U18: 1667.447 | V18: 1827.9231 | W18: 2021.5 | X18: 13.304 | Y18: 14.658 | Z18: 1272 | AA18: 410.38
A19: Hawaiian Holdings | C19: 27.55 | D19: 48.42 | R19: HA | S19: 414.71429 | T19: 411 | U19: 2837.411 | V19: 2823.7 | W19: 2957.4 | X19: 4.3366667 | Y19: 4.65 | Z19: 709.781 | AA19: 500.818
A21: Average
A22: Median
A25: Adventis Air | C25: 63.24 | R25: ADVA
A47: Source: Yahoo Finance and Bloomberg as of 4/8/2019. Shares Outstanding represent basic shares outstanding.

Sheet M&A Comps
A1: Valuation Module | I1: This document subject to the Terms of Use
A2: Acquisition Comparables Analysis ($ in Millions) | I2: © 2013 Adventis CG Training LLC
D8: Transaction | E8: LTM | F8: LTM | G8: Transaction Value | I8: EBITDA
A9: Target | B9: Buyer | C9: Date | D9: Value | E9: EBITDA | F9: Sales | G9: LTM EBITDA | H9: LTM Sales | I9: Margin
A11: Virgin America | B11: Alaska Air Group | C11: 42464 | D11: 2289.706 | E11: 195.87548 | F11: 1529.584
A12: Frontier Airlines | B12: Indigo Partners | C12: 41548 | D12: 145 | E12: 15.425532 | F12: 185.89744
A13: US Airways Group | B13: AMR Corp. (American Airlines) | C13: 41318 | D13: 4905.082 | E13: 943.285 | F13: 7213.3559
A14: AirTran Holdings | B14: Southwest Airlines | C14: 40448 | D14: 3400 | E14: 459.45946 | F14: 2595.4198
A15: Continential Airlines | B15: UAL Corp. (United Airlines) | C15: 40301 | D15: 3170 | E15: 360.22727 | F15: 3170
A16: Northwest Airlines | B16: Delta Air Lines | C16: 39552 | D16: 3100 | E16: 516.66667 | F16: 3974.359
A17: Aeromexico | B17: Investor Group led by Banamex | C17: 39339 | D17: 1248.6 | E17: 126.12121 | F17: 1248.6
A18: Midwest Air Group | B18: Northwest Airlines / TPG Partners | C18: 39306 | D18: 450 | E18: 50.561798 | F18: 405.40541
A20: Average
A21: Median
A47: Source: Company press releases, Virgin America proxy statement from June 17, 2016

Sheet WACC
A1: Valuation Module | G1: This document subject to the Terms of Use
A2: WACC Analysis ($ in Millions) | G2: © 2013 Adventis CG Training LLC
A7: Inputs | E7: Cost of Debt Calculation
A9: Risk Free Rate | C9: 0.02883 | E9: Pre-Tax Cost of Debt
A10: Yield-to-Maturity of Debt | C10: 0.0439 | E10: Corporate Tax Rate
A11: Equity Risk Premium | C11: 0.07141 | E11: After-Tax Cost of Debt
A12: Beta | C12: 1.2
A13: Corporate Tax Rate | E13: Cost of Equity Calculation
A14: Common Shares
A15: Share Price | E15: Risk Free Rate
A16: Market Value of Debt | E16: Equity Risk Premium
E17: Beta
E18: Cost of Equity
A21: WACC Calculation
E23: Amount | F23: % Total | G23: Cost of Capital
A25: Market Value of Debt
A26: Market Value of Equity
A27: Enterprise Value

Sheet DCF
A1: Valuation Module | L1: This document subject to the Terms of Use
A2: Discounted Cash Flow Analysis ($ in Millions) | L2: © 2013 Adventis CG Training LLC
H6: Fiscal Year Ended December 31,
H7: 2019E | I7: 2020E | J7: 2021E | K7: 2022E | L7: 2023E | N7: Instructions:
A8: Discounted Cash Flow Analysis
A10: Years | H10: 1 | I10: 2 | J10: 3 | K10: 4 | L10: 5
A12: Revenue | N12: Link to Income Statement
A13: Operating Expenses
A14: Operating Income | N14: Link to Income Statement
A15: Taxes @
A16: Tax-Effected EBIT
A18: Plus: Depreciation | N18: Link to Cash Flow Statement
A19: Change in Working Capital | N19: Link to Cash Flow Statement
A20: Less: Capital Expenditures | N20: Link to Cash Flow Statement
A21: Unlevered Free Cash Flow
A23: Present Value @ a Discount Rate of: | N23: Present Value = Future Value / (1 + Discount Rate)^Years
A24: Present Value of Projection Period
A27: Perpetuity Method | H27: EBITDA Exit Multiple Method
A29: Present Value of Projection Period | H29: Present Value of Projection Period
A31: 2023 Free Cash Flow | H31: 2023 EBITDA
A32: Perpetuity Growth Rate | H32: EBITDA Multiple | N32: Perpetuity Rate: 2023 FCF x [(1 + Perpetuity Growth Rate) / (Discount Rate - Perpetuity Growth Rate)]
A33: Terminal Value | H33: Terminal Value | N33: EBITDA Exit Multiple: 2023 EBITDA x EBITDA Multiple
A34: Years | H34: Years
A35: Present Value of Terminal Value | H35: Present Value of Terminal Value | N35: Present Value = Future Value / (1 + Discount Rate)^Years
A37: Total Enterprise Value | H37: Total Enterprise Value | N37: Present Value of Projection Period + Present Value of Terminal Value
A39: Implied EBITDA Multiple | H39: Implied Perpetuity Growth Rate | N39: Implied EBITDA Multiple: Terminal Value / 2023 EBITDA
N40: Implied Perpetuity Growth Rate: (Terminal Value * Discount Rate - 2023 FCF) / (Terminal Value + 2023 FCF)

Sheet Valuation Output
A1: Valuation Module | N1: This document subject to the Terms of Use
A2: Valuation Summary ($ in Millions) | N2: © 2013 Adventis CG Training LLC
D6: Target | F6: Enterprise | H6: Net | J6: Equity | L6: Shares | N6: Stock
D7: Metric | E7: Multiple | F7: Value | G7: - | H7: Debt | I7: = | J7: Value | K7: / | L7: Outstanding | M7: = | N7: Price | P7: Instructions:
A8: Comparable Companies Analysis
A10: 2019 Revenue | P10: Revenue x Multiple = Enterprise Value
A11: 2019 EBITDA | P11: EBITDA x Multiple = Enterprise Value
A12: 2019 Net Earnings | P12: Net Earnings x Multiple = Equity Value
A14: Acquisition Comparables Analysis
A16: 2018 Revenue | P16: Revenue x Multiple = Enterprise Value
A17: 2018 EBITDA | P17: EBITDA x Multiple = Enterprise Value
A19: Discounted Cash Flow Analysis
A21: Perpetuity Method | P21: Link in Enterprise Value to the DCF Tab
A22: EBITDA Exit Multiple Method
A24: Current Valuation | P24: Insert current stock price and work backwards

Sheet LBO
A1: Leveraged Buyout Module | T1: This document subject to the Terms of Use
A2: Leverage Buyout Analysis ($ in Millions) | T2: © 2013 Adventis CG Training LLC
A6: Pro Forma Financial Statements | L6: Transaction Value
E7: 2018A | F7: 2019E | G7: 2020E | H7: 2021E | I7: 2022E | J7: 2023E | L7: Current Share Price
A8: Revenue | L8: Premium
A9: Total Expenses | L9: Offer Price
A10: EBIT | L10: Shares Outstanding
A11: Interest Expense | L11: Purchase Price
A12: Earnings Before Taxes | L12: Plus: Debt
A13: Taxes @ | L13: Less: Cash
A14: Net Income | L14: Transaction Value
A16: Plus: Depreciation & Amortization | L16: 2018 EBITDA
A17: Change in Working Capital | L17: EBITDA Multiple
A18: Less: Capital Expenditures
A19: Less: Scheduled Senior Debt Paydown | L19: Sources and Uses
A20: Cash Flow Available for Debt Paydown | P20: % TV | Q20: xEBITDA | R20: Amort | S20: % Total | T20: Amount
A21: Less: Discretionary Senior Debt Paydown | L21: Senior Debt
A22: Excess Cash Flow | L22: Subordinated Debt
L23: Sponsor's Equity
A24: Debt Schedule | L24: Total Sources
A25: Senior Debt Beginning Balance
A26: Subordinate Debt Beginning Balance | L26: Transaction Value
A27: Total Beginning Balance | L27: Beginning Cash Balance
L28: Transaction Expenses
A29: Senior Debt Paydown | L29: Total Uses
A30: Subordinate Debt Paydown
A31: Total Scheduled Debt Paydown | L31: Debt / EBITDA
A33: Senior Debt Ending Balance | L33: Investor Returns
A34: Subordinate Debt Ending Balance | P34: 2019E | Q34: 2020E | R34: 2021E | S34: 2022E | T34: 2023E
A35: Total Ending Balance | L35: Years of Investment
A37: Cash Balance | L37: EBITDA
A38: Beginning Balance | L38: x EBITDA Multiple
A39: Plus: Excess Cash Flow | L39: Enterprise Value
A40: Total Ending Balance
L41: Debt
A42: Interest Expense | L42: Less: Cash
A43: Senior Debt Average Debt Balance | L43: Net Debt
A44: Subordinate Debt Average Debt Balance
A45: Average Debt Balance | L45: Equity Value
A47: Senior Debt Interest Rate | L47: Internal Rate of Return
...
